Workbook

Sheet بيانات
A1: نظام إدارة اشتراكات — نادي RCS
A2: رقم الملف | B2: اللقب | C2: الاسم | D2: تاريخ الميلاد | E2: ذكر | F2: أنثى | G2: الجنس | H2: العمر | I2: A+ | J2: A- | K2: B+ | L2: B- | M2: O+ | N2: O- | O2: AB+ | P2: AB- | Q2: فصيلة الدم | R2: / | S2: OPOW | T2: DJS | U2: FCS | V2: RCS | W2: POLICE | X2: نوع الاشتراك | Y2: تاريخ آخر دفعة | Z2: تاريخ الانتهاء | AA2: مدفوع | AB2: لم يدفع | AC2: تأمين فقط | AD2: اشتراك 300 | AE2: حالة الدفع | AF2: رسوم الاشتراك | AG2: مصاريف التأمين | AH2: حقوق المركب | AI2: المبلغ الإجمالي | AJ2: حالة التجديد | AK2: الأحد والأربعاء | AL2: الاثنين والخميس | AM2: الثلاثاء والجمعة | AN2: كل الأيام | AO2: أيام السباحة | AP2: 09:00 10:00 | AQ2: 10:00 11:00 | AR2: 19:00 20:00 | AS2: 20:00 21:00 | AT2: التوقيت | AU2: عدد أشهر الاشتراك
A3: =IF(B3="","","RCS "&TEXT(ROW()-2,"000")) | G3: =IF(B3="","",IF(E3<>"","ذكر",IF(F3<>"","أنثى",""))) | H3: =IF(D3="","",DATEDIF(D3,TODAY(),"Y")) | Q3: =IF(B3="","",IF(I3<>"","A+",IF(J3<>"","A-",IF(K3<>"","B+",IF(L3<>"","B-",IF(M3<>"","O+",IF(N3<>"","O-",IF(O3<>"","AB+",IF(P3<>"","AB-","")))))))) | X3: =IF(B3="","",IF(R3<>"","/",IF(S3<>"","OPOW",IF(T3<>"","DJS",IF(U3<>"","FCS",IF(V3<>"","RCS",IF(W3<>"","POLICE",""))))))) | Z3: =IF(Y3="","",Y3+30) | AE3: =IF(B3="","",IF(AA3<>"","مدفوع",IF(AB3<>"","لم يدفع",IF(AC3<>"","تأمين فقط",IF(AD3<>"","اشتراك 300",""))))) | AF3: =IF(OR(AE3="لم يدفع",B3=""),"",IF(OR(AE3="تأمين فقط",X3="FCS",X3="RCS"),0,IF(OR(AE3="اشتراك 300",X3="POLICE",X3="OPOW",X3="DJS"),300,IF(H3<14,1300,1500)))) | AG3: =IF(OR(AE3="لم يدفع",B3=""),"",500) | AH3: =IF(OR(AE3="لم يدفع",AE3="تأمين فقط",AE3="اشتراك 300",X3="OPOW",X3="DJS",X3="FCS",X3="RCS",X3="POLICE",B3=""),"",1000) | AI3: =IF(AE3="لم يدفع","",IF(AF3="","",AF3+AG3)) | AJ3: =IF(B3="","",IF(AE3="لم يدفع","🔒 مجمدة",IF(Z3="","",IF(Z3<TODAY(),"⛔ منتهي - يتطلب تجديد",IF(Z3-5<=TODAY(),"⚠️ قريب الانتهاء","✅ ساري"))))) | AO3: =IF(B3="","",IF(AK3<>"","الأحد والأربعاء",IF(AL3<>"","الاثنين والخميس",IF(AM3<>"","الثلاثاء والجمعة",IF(AN3<>"","كل الأيام",""))))) | AT3: =IF(B3="","",IF(AP3<>"","09:00-10:00",IF(AQ3<>"","10:00-11:00",IF(AR3<>"","19:00-20:00",IF(AS3<>"","20:00-21:00",""))))) | AU3: =IF(B3="","",COUNTA(التجديد!E3:E3))
A4: =IF(B4="","","RCS "&TEXT(ROW()-2,"000")) | G4: =IF(B4="","",IF(E4<>"","ذكر",IF(F4<>"","أنثى",""))) | H4: =IF(D4="","",DATEDIF(D4,TODAY(),"Y")) | Q4: =IF(B4="","",IF(I4<>"","A+",IF(J4<>"","A-",IF(K4<>"","B+",IF(L4<>"","B-",IF(M4<>"","O+",IF(N4<>"","O-",IF(O4<>"","AB+",IF(P4<>"","AB-","")))))))) | X4: =IF(B4="","",IF(R4<>"","/",IF(S4<>"","OPOW",IF(T4<>"","DJS",IF(U4<>"","FCS",IF(V4<>"","RCS",IF(W4<>"","POLICE",""))))))) | Z4: =IF(Y4="","",Y4+30) | AE4: =IF(B4="","",IF(AA4<>"","مدفوع",IF(AB4<>"","لم يدفع",IF(AC4<>"","تأمين فقط",IF(AD4<>"","اشتراك 300",""))))) | AF4: =IF(OR(AE4="لم يدفع",B4=""),"",IF(OR(AE4="تأمين فقط",X4="FCS",X4="RCS"),0,IF(OR(AE4="اشتراك 300",X4="POLICE",X4="OPOW",X4="DJS"),300,IF(H4<14,1300,1500)))) | AG4: =IF(OR(AE4="لم يدفع",B4=""),"",500) | AH4: =IF(OR(AE4="لم يدفع",AE4="تأمين فقط",AE4="اشتراك 300",X4="OPOW",X4="DJS",X4="FCS",X4="RCS",X4="POLICE",B4=""),"",1000) | AI4: =IF(AE4="لم يدفع","",IF(AF4="","",AF4+AG4)) | AJ4: =IF(B4="","",IF(AE4="لم يدفع","🔒 مجمدة",IF(Z4="","",IF(Z4<TODAY(),"⛔ منتهي - يتطلب تجديد",IF(Z4-5<=TODAY(),"⚠️ قريب الانتهاء","✅ ساري"))))) | AO4: =IF(B4="","",IF(AK4<>"","الأحد والأربعاء",IF(AL4<>"","الاثنين والخميس",IF(AM4<>"","الثلاثاء والجمعة",IF(AN4<>"","كل الأيام",""))))) | AT4: =IF(B4="","",IF(AP4<>"","09:00-10:00",IF(AQ4<>"","10:00-11:00",IF(AR4<>"","19:00-20:00",IF(AS4<>"","20:00-21:00",""))))) | AU4: =IF(B4="","",COUNTA(التجديد!E4:E4))
A5: =IF(B5="","","RCS "&TEXT(ROW()-2,"000")) | G5: =IF(B5="","",IF(E5<>"","ذكر",IF(F5<>"","أنثى",""))) | H5: =IF(D5="","",DATEDIF(D5,TODAY(),"Y")) | Q5: =IF(B5="","",IF(I5<>"","A+",IF(J5<>"","A-",IF(K5<>"","B+",IF(L5<>"","B-",IF(M5<>"","O+",IF(N5<>"","O-",IF(O5<>"","AB+",IF(P5<>"","AB-","")))))))) | X5: =IF(B5="","",IF(R5<>"","/",IF(S5<>"","OPOW",IF(T5<>"","DJS",IF(U5<>"","FCS",IF(V5<>"","RCS",IF(W5<>"","POLICE",""))))))) | Z5: =IF(Y5="","",Y5+30) | AE5: =IF(B5="","",IF(AA5<>"","مدفوع",IF(AB5<>"","لم يدفع",IF(AC5<>"","تأمين فقط",IF(AD5<>"","اشتراك 300",""))))) | AF5: =IF(OR(AE5="لم يدفع",B5=""),"",IF(OR(AE5="تأمين فقط",X5="FCS",X5="RCS"),0,IF(OR(AE5="اشتراك 300",X5="POLICE",X5="OPOW",X5="DJS"),300,IF(H5<14,1300,1500)))) | AG5: =IF(OR(AE5="لم يدفع",B5=""),"",500) | AH5: =IF(OR(AE5="لم يدفع",AE5="تأمين فقط",AE5="اشتراك 300",X5="OPOW",X5="DJS",X5="FCS",X5="RCS",X5="POLICE",B5=""),"",1000) | AI5: =IF(AE5="لم يدفع","",IF(AF5="","",AF5+AG5)) | AJ5: =IF(B5="","",IF(AE5="لم يدفع","🔒 مجمدة",IF(Z5="","",IF(Z5<TODAY(),"⛔ منتهي - يتطلب تجديد",IF(Z5-5<=TODAY(),"⚠️ قريب الانتهاء","✅ ساري"))))) | AO5: =IF(B5="","",IF(AK5<>"","الأحد والأربعاء",IF(AL5<>"","الاثنين والخميس",IF(AM5<>"","الثلاثاء والجمعة",IF(AN5<>"","كل الأيام",""))))) | AT5: =IF(B5="","",IF(AP5<>"","09:00-10:00",IF(AQ5<>"","10:00-11:00",IF(AR5<>"","19:00-20:00",IF(AS5<>"","20:00-21:00",""))))) | AU5: =IF(B5="","",COUNTA(التجديد!E5:E5))
A6: =IF(B6="","","RCS "&TEXT(ROW()-2,"000")) | G6: =IF(B6="","",IF(E6<>"","ذكر",IF(F6<>"","أنثى",""))) | H6: =IF(D6="","",DATEDIF(D6,TODAY(),"Y")) | Q6: =IF(B6="","",IF(I6<>"","A+",IF(J6<>"","A-",IF(K6<>"","B+",IF(L6<>"","B-",IF(M6<>"","O+",IF(N6<>"","O-",IF(O6<>"","AB+",IF(P6<>"","AB-","")))))))) | X6: =IF(B6="","",IF(R6<>"","/",IF(S6<>"","OPOW",IF(T6<>"","DJS",IF(U6<>"","FCS",IF(V6<>"","RCS",IF(W6<>"","POLICE",""))))))) | Z6: =IF(Y6="","",Y6+30) | AE6: =IF(B6="","",IF(AA6<>"","مدفوع",IF(AB6<>"","لم يدفع",IF(AC6<>"","تأمين فقط",IF(AD6<>"","اشتراك 300",""))))) | AF6: =IF(OR(AE6="لم يدفع",B6=""),"",IF(OR(AE6="تأمين فقط",X6="FCS",X6="RCS"),0,IF(OR(AE6="اشتراك 300",X6="POLICE",X6="OPOW",X6="DJS"),300,IF(H6<14,1300,1500)))) | AG6: =IF(OR(AE6="لم يدفع",B6=""),"",500) | AH6: =IF(OR(AE6="لم يدفع",AE6="تأمين فقط",AE6="اشتراك 300",X6="OPOW",X6="DJS",X6="FCS",X6="RCS",X6="POLICE",B6=""),"",1000) | AI6: =IF(AE6="لم يدفع","",IF(AF6="","",AF6+AG6)) | AJ6: =IF(B6="","",IF(AE6="لم يدفع","🔒 مجمدة",IF(Z6="","",IF(Z6<TODAY(),"⛔ منتهي - يتطلب تجديد",IF(Z6-5<=TODAY(),"⚠️ قريب الانتهاء","✅ ساري"))))) | AO6: =IF(B6="","",IF(AK6<>"","الأحد والأربعاء",IF(AL6<>"","الاثنين والخميس",IF(AM6<>"","الثلاثاء والجمعة",IF(AN6<>"","كل الأيام",""))))) | AT6: =IF(B6="","",IF(AP6<>"","09:00-10:00",IF(AQ6<>"","10:00-11:00",IF(AR6<>"","19:00-20:00",IF(AS6<>"","20:00-21:00",""))))) | AU6: =IF(B6="","",COUNTA(التجديد!E6:E6))
A7: =IF(B7="","","RCS "&TEXT(ROW()-2,"000")) | G7: =IF(B7="","",IF(E7<>"","ذكر",IF(F7<>"","أنثى",""))) | H7: =IF(D7="","",DATEDIF(D7,TODAY(),"Y")) | Q7: =IF(B7="","",IF(I7<>"","A+",IF(J7<>"","A-",IF(K7<>"","B+",IF(L7<>"","B-",IF(M7<>"","O+",IF(N7<>"","O-",IF(O7<>"","AB+",IF(P7<>"","AB-","")))))))) | X7: =IF(B7="","",IF(R7<>"","/",IF(S7<>"","OPOW",IF(T7<>"","DJS",IF(U7<>"","FCS",IF(V7<>"","RCS",IF(W7<>"","POLICE",""))))))) | Z7: =IF(Y7="","",Y7+30) | AE7: =IF(B7="","",IF(AA7<>"","مدفوع",IF(AB7<>"","لم يدفع",IF(AC7<>"","تأمين فقط",IF(AD7<>"","اشتراك 300",""))))) | AF7: =IF(OR(AE7="لم يدفع",B7=""),"",IF(OR(AE7="تأمين فقط",X7="FCS",X7="RCS"),0,IF(OR(AE7="اشتراك 300",X7="POLICE",X7="OPOW",X7="DJS"),300,IF(H7<14,1300,1500)))) | AG7: =IF(OR(AE7="لم يدفع",B7=""),"",500) | AH7: =IF(OR(AE7="لم يدفع",AE7="تأمين فقط",AE7="اشتراك 300",X7="OPOW",X7="DJS",X7="FCS",X7="RCS",X7="POLICE",B7=""),"",1000) | AI7: =IF(AE7="لم يدفع","",IF(AF7="","",AF7+AG7)) | AJ7: =IF(B7="","",IF(AE7="لم يدفع","🔒 مجمدة",IF(Z7="","",IF(Z7<TODAY(),"⛔ منتهي - يتطلب تجديد",IF(Z7-5<=TODAY(),"⚠️ قريب الانتهاء","✅ ساري"))))) | AO7: =IF(B7="","",IF(AK7<>"","الأحد والأربعاء",IF(AL7<>"","الاثنين والخميس",IF(AM7<>"","الثلاثاء والجمعة",IF(AN7<>"","كل الأيام",""))))) | AT7: =IF(B7="","",IF(AP7<>"","09:00-10:00",IF(AQ7<>"","10:00-11:00",IF(AR7<>"","19:00-20:00",IF(AS7<>"","20:00-21:00",""))))) | AU7: =IF(B7="","",COUNTA(التجديد!E7:E7))
A8: =IF(B8="","","RCS "&TEXT(ROW()-2,"000")) | G8: =IF(B8="","",IF(E8<>"","ذكر",IF(F8<>"","أنثى",""))) | H8: =IF(D8="","",DATEDIF(D8,TODAY(),"Y")) | Q8: =IF(B8="","",IF(I8<>"","A+",IF(J8<>"","A-",IF(K8<>"","B+",IF(L8<>"","B-",IF(M8<>"","O+",IF(N8<>"","O-",IF(O8<>"","AB+",IF(P8<>"","AB-","")))))))) | X8: =IF(B8="","",IF(R8<>"","/",IF(S8<>"","OPOW",IF(T8<>"","DJS",IF(U8<>"","FCS",IF(V8<>"","RCS",IF(W8<>"","POLICE",""))))))) | Z8: =IF(Y8="","",Y8+30) | AE8: =IF(B8="","",IF(AA8<>"","مدفوع",IF(AB8<>"","لم يدفع",IF(AC8<>"","تأمين فقط",IF(AD8<>"","اشتراك 300",""))))) | AF8: =IF(OR(AE8="لم يدفع",B8=""),"",IF(OR(AE8="تأمين فقط",X8="FCS",X8="RCS"),0,IF(OR(AE8="اشتراك 300",X8="POLICE",X8="OPOW",X8="DJS"),300,IF(H8<14,1300,1500)))) | AG8: =IF(OR(AE8="لم يدفع",B8=""),"",500) | AH8: =IF(OR(AE8="لم يدفع",AE8="تأمين فقط",AE8="اشتراك 300",X8="OPOW",X8="DJS",X8="FCS",X8="RCS",X8="POLICE",B8=""),"",1000) | AI8: =IF(AE8="لم يدفع","",IF(AF8="","",AF8+AG8)) | AJ8: =IF(B8="","",IF(AE8="لم يدفع","🔒 مجمدة",IF(Z8="","",IF(Z8<TODAY(),"⛔ منتهي - يتطلب تجديد",IF(Z8-5<=TODAY(),"⚠️ قريب الانتهاء","✅ ساري"))))) | AO8: =IF(B8="","",IF(AK8<>"","الأحد والأربعاء",IF(AL8<>"","الاثنين والخميس",IF(AM8<>"","الثلاثاء والجمعة",IF(AN8<>"","كل الأيام",""))))) | AT8: =IF(B8="","",IF(AP8<>"","09:00-10:00",IF(AQ8<>"","10:00-11:00",IF(AR8<>"","19:00-20:00",IF(AS8<>"","20:00-21:00",""))))) | AU8: =IF(B8="","",COUNTA(التجديد!E8:E8))
A9: =IF(B9="","","RCS "&TEXT(ROW()-2,"000")) | G9: =IF(B9="","",IF(E9<>"","ذكر",IF(F9<>"","أنثى",""))) | H9: =IF(D9="","",DATEDIF(D9,TODAY(),"Y")) | Q9: =IF(B9="","",IF(I9<>"","A+",IF(J9<>"","A-",IF(K9<>"","B+",IF(L9<>"","B-",IF(M9<>"","O+",IF(N9<>"","O-",IF(O9<>"","AB+",IF(P9<>"","AB-","")))))))) | X9: =IF(B9="","",IF(R9<>"","/",IF(S9<>"","OPOW",IF(T9<>"","DJS",IF(U9<>"","FCS",IF(V9<>"","RCS",IF(W9<>"","POLICE",""))))))) | Z9: =IF(Y9="","",Y9+30) | AE9: =IF(B9="","",IF(AA9<>"","مدفوع",IF(AB9<>"","لم يدفع",IF(AC9<>"","تأمين فقط",IF(AD9<>"","اشتراك 300",""))))) | AF9: =IF(OR(AE9="لم يدفع",B9=""),"",IF(OR(AE9="تأمين فقط",X9="FCS",X9="RCS"),0,IF(OR(AE9="اشتراك 300",X9="POLICE",X9="OPOW",X9="DJS"),300,IF(H9<14,1300,1500)))) | AG9: =IF(OR(AE9="لم يدفع",B9=""),"",500) | AH9: =IF(OR(AE9="لم يدفع",AE9="تأمين فقط",AE9="اشتراك 300",X9="OPOW",X9="DJS",X9="FCS",X9="RCS",X9="POLICE",B9=""),"",1000) | AI9: =IF(AE9="لم يدفع","",IF(AF9="","",AF9+AG9)) | AJ9: =IF(B9="","",IF(AE9="لم يدفع","🔒 مجمدة",IF(Z9="","",IF(Z9<TODAY(),"⛔ منتهي - يتطلب تجديد",IF(Z9-5<=TODAY(),"⚠️ قريب الانتهاء","✅ ساري"))))) | AO9: =IF(B9="","",IF(AK9<>"","الأحد والأربعاء",IF(AL9<>"","الاثنين والخميس",IF(AM9<>"","الثلاثاء والجمعة",IF(AN9<>"","كل الأيام",""))))) | AT9: =IF(B9="","",IF(AP9<>"","09:00-10:00",IF(AQ9<>"","10:00-11:00",IF(AR9<>"","19:00-20:00",IF(AS9<>"","20:00-21:00",""))))) | AU9: =IF(B9="","",COUNTA(التجديد!E9:E9))
A10: =IF(B10="","","RCS "&TEXT(ROW()-2,"000")) | G10: =IF(B10="","",IF(E10<>"","ذكر",IF(F10<>"","أنثى",""))) | H10: =IF(D10="","",DATEDIF(D10,TODAY(),"Y")) | Q10: =IF(B10="","",IF(I10<>"","A+",IF(J10<>"","A-",IF(K10<>"","B+",IF(L10<>"","B-",IF(M10<>"","O+",IF(N10<>"","O-",IF(O10<>"","AB+",IF(P10<>"","AB-","")))))))) | X10: =IF(B10="","",IF(R10<>"","/",IF(S10<>"","OPOW",IF(T10<>"","DJS",IF(U10<>"","FCS",IF(V10<>"","RCS",IF(W10<>"","POLICE",""))))))) | Z10: =IF(Y10="","",Y10+30) | AE10: =IF(B10="","",IF(AA10<>"","مدفوع",IF(AB10<>"","لم يدفع",IF(AC10<>"","تأمين فقط",IF(AD10<>"","اشتراك 300",""))))) | AF10: =IF(OR(AE10="لم يدفع",B10=""),"",IF(OR(AE10="تأمين فقط",X10="FCS",X10="RCS"),0,IF(OR(AE10="اشتراك 300",X10="POLICE",X10="OPOW",X10="DJS"),300,IF(H10<14,1300,1500)))) | AG10: =IF(OR(AE10="لم يدفع",B10=""),"",500) | AH10: =IF(OR(AE10="لم يدفع",AE10="تأمين فقط",AE10="اشتراك 300",X10="OPOW",X10="DJS",X10="FCS",X10="RCS",X10="POLICE",B10=""),"",1000) | AI10: =IF(AE10="لم يدفع","",IF(AF10="","",AF10+AG10)) | AJ10: =IF(B10="","",IF(AE10="لم يدفع","🔒 مجمدة",IF(Z10="","",IF(Z10<TODAY(),"⛔ منتهي - يتطلب تجديد",IF(Z10-5<=TODAY(),"⚠️ قريب الانتهاء","✅ ساري"))))) | AO10: =IF(B10="","",IF(AK10<>"","الأحد والأربعاء",IF(AL10<>"","الاثنين والخميس",IF(AM10<>"","الثلاثاء والجمعة",IF(AN10<>"","كل الأيام",""))))) | AT10: =IF(B10="","",IF(AP10<>"","09:00-10:00",IF(AQ10<>"","10:00-11:00",IF(AR10<>"","19:00-20:00",IF(AS10<>"","20:00-21:00",""))))) | AU10: =IF(B10="","",COUNTA(التجديد!E10:E10))
A11: =IF(B11="","","RCS "&TEXT(ROW()-2,"000")) | G11: =IF(B11="","",IF(E11<>"","ذكر",IF(F11<>"","أنثى",""))) | H11: =IF(D11="","",DATEDIF(D11,TODAY(),"Y")) | Q11: =IF(B11="","",IF(I11<>"","A+",IF(J11<>"","A-",IF(K11<>"","B+",IF(L11<>"","B-",IF(M11<>"","O+",IF(N11<>"","O-",IF(O11<>"","AB+",IF(P11<>"","AB-","")))))))) | X11: =IF(B11="","",IF(R11<>"","/",IF(S11<>"","OPOW",IF(T11<>"","DJS",IF(U11<>"","FCS",IF(V11<>"","RCS",IF(W11<>"","POLICE",""))))))) | Z11: =IF(Y11="","",Y11+30) | AE11: =IF(B11="","",IF(AA11<>"","مدفوع",IF(AB11<>"","لم يدفع",IF(AC11<>"","تأمين فقط",IF(AD11<>"","اشتراك 300",""))))) | AF11: =IF(OR(AE11="لم يدفع",B11=""),"",IF(OR(AE11="تأمين فقط",X11="FCS",X11="RCS"),0,IF(OR(AE11="اشتراك 300",X11="POLICE",X11="OPOW",X11="DJS"),300,IF(H11<14,1300,1500)))) | AG11: =IF(OR(AE11="لم يدفع",B11=""),"",500) | AH11: =IF(OR(AE11="لم يدفع",AE11="تأمين فقط",AE11="اشتراك 300",X11="OPOW",X11="DJS",X11="FCS",X11="RCS",X11="POLICE",B11=""),"",1000) | AI11: =IF(AE11="لم يدفع","",IF(AF11="","",AF11+AG11)) | AJ11: =IF(B11="","",IF(AE11="لم يدفع","🔒 مجمدة",IF(Z11="","",IF(Z11<TODAY(),"⛔ منتهي - يتطلب تجديد",IF(Z11-5<=TODAY(),"⚠️ قريب الانتهاء","✅ ساري"))))) | AO11: =IF(B11="","",IF(AK11<>"","الأحد والأربعاء",IF(AL11<>"","الاثنين والخميس",IF(AM11<>"","الثلاثاء والجمعة",IF(AN11<>"","كل الأيام",""))))) | AT11: =IF(B11="","",IF(AP11<>"","09:00-10:00",IF(AQ11<>"","10:00-11:00",IF(AR11<>"","19:00-20:00",IF(AS11<>"","20:00-21:00",""))))) | AU11: =IF(B11="","",COUNTA(التجديد!E11:E11))
A12: =IF(B12="","","RCS "&TEXT(ROW()-2,"000")) | G12: =IF(B12="","",IF(E12<>"","ذكر",IF(F12<>"","أنثى",""))) | H12: =IF(D12="","",DATEDIF(D12,TODAY(),"Y")) | Q12: =IF(B12="","",IF(I12<>"","A+",IF(J12<>"","A-",IF(K12<>"","B+",IF(L12<>"","B-",IF(M12<>"","O+",IF(N12<>"","O-",IF(O12<>"","AB+",IF(P12<>"","AB-","")))))))) | X12: =IF(B12="","",IF(R12<>"","/",IF(S12<>"","OPOW",IF(T12<>"","DJS",IF(U12<>"","FCS",IF(V12<>"","RCS",IF(W12<>"","POLICE",""))))))) | Z12: =IF(Y12="","",Y12+30) | AE12: =IF(B12="","",IF(AA12<>"","مدفوع",IF(AB12<>"","لم يدفع",IF(AC12<>"","تأمين فقط",IF(AD12<>"","اشتراك 300",""))))) | AF12: =IF(OR(AE12="لم يدفع",B12=""),"",IF(OR(AE12="تأمين فقط",X12="FCS",X12="RCS"),0,IF(OR(AE12="اشتراك 300",X12="POLICE",X12="OPOW",X12="DJS"),300,IF(H12<14,1300,1500)))) | AG12: =IF(OR(AE12="لم يدفع",B12=""),"",500) | AH12: =IF(OR(AE12="لم يدفع",AE12="تأمين فقط",AE12="اشتراك 300",X12="OPOW",X12="DJS",X12="FCS",X12="RCS",X12="POLICE",B12=""),"",1000) | AI12: =IF(AE12="لم يدفع","",IF(AF12="","",AF12+AG12)) | AJ12: =IF(B12="","",IF(AE12="لم يدفع","🔒 مجمدة",IF(Z12="","",IF(Z12<TODAY(),"⛔ منتهي - يتطلب تجديد",IF(Z12-5<=TODAY(),"⚠️ قريب الانتهاء","✅ ساري"))))) | AO12: =IF(B12="","",IF(AK12<>"","الأحد والأربعاء",IF(AL12<>"","الاثنين والخميس",IF(AM12<>"","الثلاثاء والجمعة",IF(AN12<>"","كل الأيام",""))))) | AT12: =IF(B12="","",IF(AP12<>"","09:00-10:00",IF(AQ12<>"","10:00-11:00",IF(AR12<>"","19:00-20:00",IF(AS12<>"","20:00-21:00",""))))) | AU12: =IF(B12="","",COUNTA(التجديد!E12:E12))
A13: =IF(B13="","","RCS "&TEXT(ROW()-2,"000")) | G13: =IF(B13="","",IF(E13<>"","ذكر",IF(F13<>"","أنثى",""))) | H13: =IF(D13="","",DATEDIF(D13,TODAY(),"Y")) | Q13: =IF(B13="","",IF(I13<>"","A+",IF(J13<>"","A-",IF(K13<>"","B+",IF(L13<>"","B-",IF(M13<>"","O+",IF(N13<>"","O-",IF(O13<>"","AB+",IF(P13<>"","AB-","")))))))) | X13: =IF(B13="","",IF(R13<>"","/",IF(S13<>"","OPOW",IF(T13<>"","DJS",IF(U13<>"","FCS",IF(V13<>"","RCS",IF(W13<>"","POLICE",""))))))) | Z13: =IF(Y13="","",Y13+30) | AE13: =IF(B13="","",IF(AA13<>"","مدفوع",IF(AB13<>"","لم يدفع",IF(AC13<>"","تأمين فقط",IF(AD13<>"","اشتراك 300",""))))) | AF13: =IF(OR(AE13="لم يدفع",B13=""),"",IF(OR(AE13="تأمين فقط",X13="FCS",X13="RCS"),0,IF(OR(AE13="اشتراك 300",X13="POLICE",X13="OPOW",X13="DJS"),300,IF(H13<14,1300,1500)))) | AG13: =IF(OR(AE13="لم يدفع",B13=""),"",500) | AH13: =IF(OR(AE13="لم يدفع",AE13="تأمين فقط",AE13="اشتراك 300",X13="OPOW",X13="DJS",X13="FCS",X13="RCS",X13="POLICE",B13=""),"",1000) | AI13: =IF(AE13="لم يدفع","",IF(AF13="","",AF13+AG13)) | AJ13: =IF(B13="","",IF(AE13="لم يدفع","🔒 مجمدة",IF(Z13="","",IF(Z13<TODAY(),"⛔ منتهي - يتطلب تجديد",IF(Z13-5<=TODAY(),"⚠️ قريب الانتهاء","✅ ساري"))))) | AO13: =IF(B13="","",IF(AK13<>"","الأحد والأربعاء",IF(AL13<>"","الاثنين والخميس",IF(AM13<>"","الثلاثاء والجمعة",IF(AN13<>"","كل الأيام",""))))) | AT13: =IF(B13="","",IF(AP13<>"","09:00-10:00",IF(AQ13<>"","10:00-11:00",IF(AR13<>"","19:00-20:00",IF(AS13<>"","20:00-21:00",""))))) | AU13: =IF(B13="","",COUNTA(التجديد!E13:E13))
A14: =IF(B14="","","RCS "&TEXT(ROW()-2,"000")) | G14: =IF(B14="","",IF(E14<>"","ذكر",IF(F14<>"","أنثى",""))) | H14: =IF(D14="","",DATEDIF(D14,TODAY(),"Y")) | Q14: =IF(B14="","",IF(I14<>"","A+",IF(J14<>"","A-",IF(K14<>"","B+",IF(L14<>"","B-",IF(M14<>"","O+",IF(N14<>"","O-",IF(O14<>"","AB+",IF(P14<>"","AB-","")))))))) | X14: =IF(B14="","",IF(R14<>"","/",IF(S14<>"","OPOW",IF(T14<>"","DJS",IF(U14<>"","FCS",IF(V14<>"","RCS",IF(W14<>"","POLICE",""))))))) | Z14: =IF(Y14="","",Y14+30) | AE14: =IF(B14="","",IF(AA14<>"","مدفوع",IF(AB14<>"","لم يدفع",IF(AC14<>"","تأمين فقط",IF(AD14<>"","اشتراك 300",""))))) | AF14: =IF(OR(AE14="لم يدفع",B14=""),"",IF(OR(AE14="تأمين فقط",X14="FCS",X14="RCS"),0,IF(OR(AE14="اشتراك 300",X14="POLICE",X14="OPOW",X14="DJS"),300,IF(H14<14,1300,1500)))) | AG14: =IF(OR(AE14="لم يدفع",B14=""),"",500) | AH14: =IF(OR(AE14="لم يدفع",AE14="تأمين فقط",AE14="اشتراك 300",X14="OPOW",X14="DJS",X14="FCS",X14="RCS",X14="POLICE",B14=""),"",1000) | AI14: =IF(AE14="لم يدفع","",IF(AF14="","",AF14+AG14)) | AJ14: =IF(B14="","",IF(AE14="لم يدفع","🔒 مجمدة",IF(Z14="","",IF(Z14<TODAY(),"⛔ منتهي - يتطلب تجديد",IF(Z14-5<=TODAY(),"⚠️ قريب الانتهاء","✅ ساري"))))) | AO14: =IF(B14="","",IF(AK14<>"","الأحد والأربعاء",IF(AL14<>"","الاثنين والخميس",IF(AM14<>"","الثلاثاء والجمعة",IF(AN14<>"","كل الأيام",""))))) | AT14: =IF(B14="","",IF(AP14<>"","09:00-10:00",IF(AQ14<>"","10:00-11:00",IF(AR14<>"","19:00-20:00",IF(AS14<>"","20:00-21:00",""))))) | AU14: =IF(B14="","",COUNTA(التجديد!E14:E14))
... A202: =IF(B202="","","RCS "&TEXT(ROW()-2,"000")) | G202: =IF(B202="","",IF(E202<>"","ذكر",IF(F202<>"","أنثى",""))) | H202: =IF(D202="","",DATEDIF(D202,TODAY(),"Y")) | Q202: =IF(B202="","",IF(I202<>"","A+",IF(J202<>"","A-",IF(K202<>"","B+",IF(L202<>"","B-",IF(M202<>"","O+",IF(N202<>"","O-",IF(O202<>"","AB+",IF(P202<>"","AB-","")))))))) | X202: =IF(B202="","",IF(R202<>"","/",IF(S202<>"","OPOW",IF(T202<>"","DJS",IF(U202<>"","FCS",IF(V202<>"","RCS",IF(W202<>"","POLICE",""))))))) | Z202: =IF(Y202="","",Y202+30) | AE202: =IF(B202="","",IF(AA202<>"","مدفوع",IF(AB202<>"","لم يدفع",IF(AC202<>"","تأمين فقط",IF(AD202<>"","اشتراك 300",""))))) | AF202: =IF(OR(AE202="لم يدفع",B202=""),"",IF(OR(AE202="تأمين فقط",X202="FCS",X202="RCS"),0,IF(OR(AE202="اشتراك 300",X202="POLICE",X202="OPOW",X202="DJS"),300,IF(H202<14,1300,1500)))) | AG202: =IF(OR(AE202="لم يدفع",B202=""),"",500) | AH202: =IF(OR(AE202="لم يدفع",AE202="تأمين فقط",AE202="اشتراك 300",X202="OPOW",X202="DJS",X202="FCS",X202="RCS",X202="POLICE",B202=""),"",1000) | AI202: =IF(AE202="لم يدفع","",IF(AF202="","",AF202+AG202)) | AJ202: =IF(B202="","",IF(AE202="لم يدفع","🔒 مجمدة",IF(Z202="","",IF(Z202<TODAY(),"⛔ منتهي - يتطلب تجديد",IF(Z202-5<=TODAY(),"⚠️ قريب الانتهاء","✅ ساري"))))) | AO202: =IF(B202="","",IF(AK202<>"","الأحد والأربعاء",IF(AL202<>"","الاثنين والخميس",IF(AM202<>"","الثلاثاء والجمعة",IF(AN202<>"","كل الأيام",""))))) | AT202: =IF(B202="","",IF(AP202<>"","09:00-10:00",IF(AQ202<>"","10:00-11:00",IF(AR202<>"","19:00-20:00",IF(AS202<>"","20:00-21:00",""))))) | AU202: =IF(B202="","",COUNTA(التجديد!E202:E202))

Sheet لوحة_التحكم
A1: 📊 لوحة التحكم — إحصائيات الاشتراكات — نادي RCS
B3: 💰 الإحصائيات المالية | E3: 👥 إحصائيات المنخرطين | H3: 📋 فئات الاشتراك | K3: 🔄 حالة التجديد
B4: إجمالي رسوم الاشتراك | C4: =SUMIFS(بيانات!AF3:AF202,بيانات!AE3:AE202,"<>لم يدفع",بيانات!B3:B202,"<>") | E4: إجمالي المنخرطين | F4: =COUNTA(بيانات!B3:B202) | H4: اشتراك عادي (/) | I4: =COUNTIF(بيانات!X3:X202,"/") | K4: ✅ سارية | L4: =COUNTIF(بيانات!AJ3:AJ202,"*ساري*")
B5: إجمالي مصاريف التأمين | C5: =SUMIFS(بيانات!AG3:AG202,بيانات!AE3:AE202,"<>لم يدفع",بيانات!B3:B202,"<>") | E5: ✅ مدفوع | F5: =COUNTIF(بيانات!AE3:AE202,"مدفوع") | H5: OPOW | I5: =COUNTIF(بيانات!X3:X202,"OPOW") | K5: ⚠️ قريبة الانتهاء | L5: =COUNTIF(بيانات!AJ3:AJ202,"*قريب*")
B6: حقوق المركب (مستثناة) | C6: =SUMIFS(بيانات!AH3:AH202,بيانات!AE3:AE202,"<>لم يدفع",بيانات!B3:B202,"<>") | E6: ❌ لم يدفع | F6: =COUNTIF(بيانات!AE3:AE202,"لم يدفع") | H6: DJS | I6: =COUNTIF(بيانات!X3:X202,"DJS") | K6: ⛔ منتهية | L6: =COUNTIF(بيانات!AJ3:AJ202,"*منتهي*")
B7: الإيرادات (رسوم + تأمين) | C7: =C4+C5 | E7: 🔵 تأمين فقط | F7: =COUNTIF(بيانات!AE3:AE202,"تأمين فقط") | H7: FCS | I7: =COUNTIF(بيانات!X3:X202,"FCS") | K7: 🔒 مجمدة | L7: =COUNTIF(بيانات!AJ3:AJ202,"*مجمدة*")
B8: اشتراكات عادية (1300) | C8: =SUMIFS(بيانات!AI3:AI202,بيانات!AF3:AF202,1300,بيانات!AE3:AE202,"<>لم يدفع") | E8: 🟠 اشتراك 300 | F8: =COUNTIF(بيانات!AE3:AE202,"اشتراك 300") | H8: RCS | I8: =COUNTIF(بيانات!X3:X202,"RCS")
B9: اشتراكات عادية (1500) | C9: =SUMIFS(بيانات!AI3:AI202,بيانات!AF3:AF202,1500,بيانات!AE3:AE202,"<>لم يدفع") | E9: كبار (14+) | F9: =COUNTIFS(بيانات!H3:H202,">=14",بيانات!B3:B202,"<>") | H9: POLICE | I9: =COUNTIF(بيانات!X3:X202,"POLICE")
B10: إيرادات OPOW/DJS | C10: =SUMIFS(بيانات!AI3:AI202,بيانات!X3:X202,"OPOW",بيانات!AE3:AE202,"<>لم يدفع")+SUMIFS(بيانات!AI3:AI202,بيانات!X3:X202,"DJS",بيانات!AE3:AE202,"<>لم يدفع") | E10: صغار (أقل من 14) | F10: =COUNTIFS(بيانات!H3:H202,"<14",بيانات!H3:H202,"<>",بيانات!B3:B202,"<>")
B11: متوسط الدفعة | C11: =IFERROR(AVERAGEIFS(بيانات!AI3:AI202,بيانات!AE3:AE202,"<>لم يدفع",بيانات!B3:B202,"<>"),0) | E11: ذكور | F11: =COUNTIF(بيانات!G3:G202,"ذكر")
E12: إناث | F12: =COUNTIF(بيانات!G3:G202,"أنثى")
B15: 🕐 أفواج التوقيت | E15: 🏊 أيام السباحة | H15: 🩸 فصائل الدم | K15: 💳 ملخص مالي تفصيلي
B16: 09:00-10:00 | C16: =COUNTIF(بيانات!AT3:AT202,"09:00-10:00") | E16: الأحد والأربعاء | F16: =COUNTIF(بيانات!AO3:AO202,"الأحد والأربعاء") | H16: A+ | I16: =COUNTIF(بيانات!Q3:Q202,"A+") | K16: رسوم 300 دج × عدد | L16: =COUNTIF(بيانات!AF3:AF202,300)&" منخرط"
B17: 10:00-11:00 | C17: =COUNTIF(بيانات!AT3:AT202,"10:00-11:00") | E17: الاثنين والخميس | F17: =COUNTIF(بيانات!AO3:AO202,"الاثنين والخميس") | H17: A- | I17: =COUNTIF(بيانات!Q3:Q202,"A-") | K17: مجموع رسوم 300 | L17: =SUMIF(بيانات!AF3:AF202,300,بيانات!AF3:AF202)
B18: 19:00-20:00 | C18: =COUNTIF(بيانات!AT3:AT202,"19:00-20:00") | E18: الثلاثاء والجمعة | F18: =COUNTIF(بيانات!AO3:AO202,"الثلاثاء والجمعة") | H18: B+ | I18: =COUNTIF(بيانات!Q3:Q202,"B+") | K18: رسوم 1300 دج × عدد | L18: =COUNTIF(بيانات!AF3:AF202,1300)&" منخرط"
B19: 20:00-21:00 | C19: =COUNTIF(بيانات!AT3:AT202,"20:00-21:00") | E19: كل الأيام | F19: =COUNTIF(بيانات!AO3:AO202,"كل الأيام") | H19: B- | I19: =COUNTIF(بيانات!Q3:Q202,"B-") | K19: مجموع رسوم 1300 | L19: =SUMIF(بيانات!AF3:AF202,1300,بيانات!AF3:AF202)
H20: O+ | I20: =COUNTIF(بيانات!Q3:Q202,"O+") | K20: رسوم 1500 دج × عدد | L20: =COUNTIF(بيانات!AF3:AF202,1500)&" منخرط"
H21: O- | I21: =COUNTIF(بيانات!Q3:Q202,"O-") | K21: مجموع رسوم 1500 | L21: =SUMIF(بيانات!AF3:AF202,1500,بيانات!AF3:AF202)
H22: AB+ | I22: =COUNTIF(بيانات!Q3:Q202,"AB+") | K22: تأمين مُحصَّل | L22: =SUMIF(بيانات!AE3:AE202,"<>لم يدفع",بيانات!AG3:AG202)
H23: AB- | I23: =COUNTIF(بيانات!Q3:Q202,"AB-") | K23: حقوق مركب مُحصَّلة | L23: =SUMIFS(بيانات!AH3:AH202,بيانات!AE3:AE202,"<>لم يدفع",بيانات!B3:B202,"<>")
A35: ✦ نادي RCS | منظومة إدارة الاشتراكات | جميع الحقوق محفوظة ✦

Sheet حقوق_المركب
A1: 🏊 سجل حقوق المركب — نادي RCS
A2: رقم الملف | B2: اللقب | C2: الاسم | D2: رسوم الاشتراك | E2: حقوق المركب | F2: المبلغ الإجمالي | G2: حالة الدفع
A3: =IF(بيانات!AH3=1000,بيانات!A3,"") | B3: =IF(بيانات!AH3=1000,بيانات!B3,"") | C3: =IF(بيانات!AH3=1000,بيانات!C3,"") | D3: =IF(بيانات!AH3=1000,بيانات!AF3,"") | E3: =IF(بيانات!AH3=1000,بيانات!AH3,"") | F3: =IF(بيانات!AH3=1000,بيانات!AI3,"") | G3: =IF(بيانات!AH3=1000,بيانات!AE3,"")
A4: =IF(بيانات!AH4=1000,بيانات!A4,"") | B4: =IF(بيانات!AH4=1000,بيانات!B4,"") | C4: =IF(بيانات!AH4=1000,بيانات!C4,"") | D4: =IF(بيانات!AH4=1000,بيانات!AF4,"") | E4: =IF(بيانات!AH4=1000,بيانات!AH4,"") | F4: =IF(بيانات!AH4=1000,بيانات!AI4,"") | G4: =IF(بيانات!AH4=1000,بيانات!AE4,"")
A5: =IF(بيانات!AH5=1000,بيانات!A5,"") | B5: =IF(بيانات!AH5=1000,بيانات!B5,"") | C5: =IF(بيانات!AH5=1000,بيانات!C5,"") | D5: =IF(بيانات!AH5=1000,بيانات!AF5,"") | E5: =IF(بيانات!AH5=1000,بيانات!AH5,"") | F5: =IF(بيانات!AH5=1000,بيانات!AI5,"") | G5: =IF(بيانات!AH5=1000,بيانات!AE5,"")
A6: =IF(بيانات!AH6=1000,بيانات!A6,"") | B6: =IF(بيانات!AH6=1000,بيانات!B6,"") | C6: =IF(بيانات!AH6=1000,بيانات!C6,"") | D6: =IF(بيانات!AH6=1000,بيانات!AF6,"") | E6: =IF(بيانات!AH6=1000,بيانات!AH6,"") | F6: =IF(بيانات!AH6=1000,بيانات!AI6,"") | G6: =IF(بيانات!AH6=1000,بيانات!AE6,"")
A7: =IF(بيانات!AH7=1000,بيانات!A7,"") | B7: =IF(بيانات!AH7=1000,بيانات!B7,"") | C7: =IF(بيانات!AH7=1000,بيانات!C7,"") | D7: =IF(بيانات!AH7=1000,بيانات!AF7,"") | E7: =IF(بيانات!AH7=1000,بيانات!AH7,"") | F7: =IF(بيانات!AH7=1000,بيانات!AI7,"") | G7: =IF(بيانات!AH7=1000,بيانات!AE7,"")
A8: =IF(بيانات!AH8=1000,بيانات!A8,"") | B8: =IF(بيانات!AH8=1000,بيانات!B8,"") | C8: =IF(بيانات!AH8=1000,بيانات!C8,"") | D8: =IF(بيانات!AH8=1000,بيانات!AF8,"") | E8: =IF(بيانات!AH8=1000,بيانات!AH8,"") | F8: =IF(بيانات!AH8=1000,بيانات!AI8,"") | G8: =IF(بيانات!AH8=1000,بيانات!AE8,"")
A9: =IF(بيانات!AH9=1000,بيانات!A9,"") | B9: =IF(بيانات!AH9=1000,بيانات!B9,"") | C9: =IF(بيانات!AH9=1000,بيانات!C9,"") | D9: =IF(بيانات!AH9=1000,بيانات!AF9,"") | E9: =IF(بيانات!AH9=1000,بيانات!AH9,"") | F9: =IF(بيانات!AH9=1000,بيانات!AI9,"") | G9: =IF(بيانات!AH9=1000,بيانات!AE9,"")
A10: =IF(بيانات!AH10=1000,بيانات!A10,"") | B10: =IF(بيانات!AH10=1000,بيانات!B10,"") | C10: =IF(بيانات!AH10=1000,بيانات!C10,"") | D10: =IF(بيانات!AH10=1000,بيانات!AF10,"") | E10: =IF(بيانات!AH10=1000,بيانات!AH10,"") | F10: =IF(بيانات!AH10=1000,بيانات!AI10,"") | G10: =IF(بيانات!AH10=1000,بيانات!AE10,"")
A11: =IF(بيانات!AH11=1000,بيانات!A11,"") | B11: =IF(بيانات!AH11=1000,بيانات!B11,"") | C11: =IF(بيانات!AH11=1000,بيانات!C11,"") | D11: =IF(بيانات!AH11=1000,بيانات!AF11,"") | E11: =IF(بيانات!AH11=1000,بيانات!AH11,"") | F11: =IF(بيانات!AH11=1000,بيانات!AI11,"") | G11: =IF(بيانات!AH11=1000,بيانات!AE11,"")
A12: =IF(بيانات!AH12=1000,بيانات!A12,"") | B12: =IF(بيانات!AH12=1000,بيانات!B12,"") | C12: =IF(بيانات!AH12=1000,بيانات!C12,"") | D12: =IF(بيانات!AH12=1000,بيانات!AF12,"") | E12: =IF(بيانات!AH12=1000,بيانات!AH12,"") | F12: =IF(بيانات!AH12=1000,بيانات!AI12,"") | G12: =IF(بيانات!AH12=1000,بيانات!AE12,"")
A13: =IF(بيانات!AH13=1000,بيانات!A13,"") | B13: =IF(بيانات!AH13=1000,بيانات!B13,"") | C13: =IF(بيانات!AH13=1000,بيانات!C13,"") | D13: =IF(بيانات!AH13=1000,بيانات!AF13,"") | E13: =IF(بيانات!AH13=1000,بيانات!AH13,"") | F13: =IF(بيانات!AH13=1000,بيانات!AI13,"") | G13: =IF(بيانات!AH13=1000,بيانات!AE13,"")
A14: =IF(بيانات!AH14=1000,بيانات!A14,"") | B14: =IF(بيانات!AH14=1000,بيانات!B14,"") | C14: =IF(بيانات!AH14=1000,بيانات!C14,"") | D14: =IF(بيانات!AH14=1000,بيانات!AF14,"") | E14: =IF(بيانات!AH14=1000,بيانات!AH14,"") | F14: =IF(بيانات!AH14=1000,بيانات!AI14,"") | G14: =IF(بيانات!AH14=1000,بيانات!AE14,"")
... A202: =IF(بيانات!AH202=1000,بيانات!A202,"") | B202: =IF(بيانات!AH202=1000,بيانات!B202,"") | C202: =IF(بيانات!AH202=1000,بيانات!C202,"") | D202: =IF(بيانات!AH202=1000,بيانات!AF202,"") | E202: =IF(بيانات!AH202=1000,بيانات!AH202,"") | F202: =IF(بيانات!AH202=1000,بيانات!AI202,"") | G202: =IF(بيانات!AH202=1000,بيانات!AE202,"")

Sheet التجديد
A1: 🔄 سجل تجديد الاشتراكات — نادي RCS
A2: رقم الملف | B2: اللقب | C2: الاسم | D2: نهاية الاشتراك السابق | E2: تاريخ التجديد | F2: نهاية الشهر الجديد | G2: مبلغ التجديد | H2: حالة الدفع | I2: حالة التجديد
A3: =IF(بيانات!B3<>"",بيانات!A3,"") | B3: =IF(بيانات!B3<>"",بيانات!B3,"") | C3: =IF(بيانات!B3<>"",بيانات!C3,"") | D3: =IF(بيانات!B3<>"",بيانات!Z3,"") | F3: =IF(E3="","",E3+30) | H3: =IF(بيانات!B3<>"",بيانات!AE3,"") | I3: =IF(بيانات!B3<>"",بيانات!AJ3,"")
A4: =IF(بيانات!B4<>"",بيانات!A4,"") | B4: =IF(بيانات!B4<>"",بيانات!B4,"") | C4: =IF(بيانات!B4<>"",بيانات!C4,"") | D4: =IF(بيانات!B4<>"",بيانات!Z4,"") | F4: =IF(E4="","",E4+30) | H4: =IF(بيانات!B4<>"",بيانات!AE4,"") | I4: =IF(بيانات!B4<>"",بيانات!AJ4,"")
A5: =IF(بيانات!B5<>"",بيانات!A5,"") | B5: =IF(بيانات!B5<>"",بيانات!B5,"") | C5: =IF(بيانات!B5<>"",بيانات!C5,"") | D5: =IF(بيانات!B5<>"",بيانات!Z5,"") | F5: =IF(E5="","",E5+30) | H5: =IF(بيانات!B5<>"",بيانات!AE5,"") | I5: =IF(بيانات!B5<>"",بيانات!AJ5,"")
A6: =IF(بيانات!B6<>"",بيانات!A6,"") | B6: =IF(بيانات!B6<>"",بيانات!B6,"") | C6: =IF(بيانات!B6<>"",بيانات!C6,"") | D6: =IF(بيانات!B6<>"",بيانات!Z6,"") | F6: =IF(E6="","",E6+30) | H6: =IF(بيانات!B6<>"",بيانات!AE6,"") | I6: =IF(بيانات!B6<>"",بيانات!AJ6,"")
A7: =IF(بيانات!B7<>"",بيانات!A7,"") | B7: =IF(بيانات!B7<>"",بيانات!B7,"") | C7: =IF(بيانات!B7<>"",بيانات!C7,"") | D7: =IF(بيانات!B7<>"",بيانات!Z7,"") | F7: =IF(E7="","",E7+30) | H7: =IF(بيانات!B7<>"",بيانات!AE7,"") | I7: =IF(بيانات!B7<>"",بيانات!AJ7,"")
A8: =IF(بيانات!B8<>"",بيانات!A8,"") | B8: =IF(بيانات!B8<>"",بيانات!B8,"") | C8: =IF(بيانات!B8<>"",بيانات!C8,"") | D8: =IF(بيانات!B8<>"",بيانات!Z8,"") | F8: =IF(E8="","",E8+30) | H8: =IF(بيانات!B8<>"",بيانات!AE8,"") | I8: =IF(بيانات!B8<>"",بيانات!AJ8,"")
A9: =IF(بيانات!B9<>"",بيانات!A9,"") | B9: =IF(بيانات!B9<>"",بيانات!B9,"") | C9: =IF(بيانات!B9<>"",بيانات!C9,"") | D9: =IF(بيانات!B9<>"",بيانات!Z9,"") | F9: =IF(E9="","",E9+30) | H9: =IF(بيانات!B9<>"",بيانات!AE9,"") | I9: =IF(بيانات!B9<>"",بيانات!AJ9,"")
A10: =IF(بيانات!B10<>"",بيانات!A10,"") | B10: =IF(بيانات!B10<>"",بيانات!B10,"") | C10: =IF(بيانات!B10<>"",بيانات!C10,"") | D10: =IF(بيانات!B10<>"",بيانات!Z10,"") | F10: =IF(E10="","",E10+30) | H10: =IF(بيانات!B10<>"",بيانات!AE10,"") | I10: =IF(بيانات!B10<>"",بيانات!AJ10,"")
A11: =IF(بيانات!B11<>"",بيانات!A11,"") | B11: =IF(بيانات!B11<>"",بيانات!B11,"") | C11: =IF(بيانات!B11<>"",بيانات!C11,"") | D11: =IF(بيانات!B11<>"",بيانات!Z11,"") | F11: =IF(E11="","",E11+30) | H11: =IF(بيانات!B11<>"",بيانات!AE11,"") | I11: =IF(بيانات!B11<>"",بيانات!AJ11,"")
A12: =IF(بيانات!B12<>"",بيانات!A12,"") | B12: =IF(بيانات!B12<>"",بيانات!B12,"") | C12: =IF(بيانات!B12<>"",بيانات!C12,"") | D12: =IF(بيانات!B12<>"",بيانات!Z12,"") | F12: =IF(E12="","",E12+30) | H12: =IF(بيانات!B12<>"",بيانات!AE12,"") | I12: =IF(بيانات!B12<>"",بيانات!AJ12,"")
A13: =IF(بيانات!B13<>"",بيانات!A13,"") | B13: =IF(بيانات!B13<>"",بيانات!B13,"") | C13: =IF(بيانات!B13<>"",بيانات!C13,"") | D13: =IF(بيانات!B13<>"",بيانات!Z13,"") | F13: =IF(E13="","",E13+30) | H13: =IF(بيانات!B13<>"",بيانات!AE13,"") | I13: =IF(بيانات!B13<>"",بيانات!AJ13,"")
A14: =IF(بيانات!B14<>"",بيانات!A14,"") | B14: =IF(بيانات!B14<>"",بيانات!B14,"") | C14: =IF(بيانات!B14<>"",بيانات!C14,"") | D14: =IF(بيانات!B14<>"",بيانات!Z14,"") | F14: =IF(E14="","",E14+30) | H14: =IF(بيانات!B14<>"",بيانات!AE14,"") | I14: =IF(بيانات!B14<>"",بيانات!AJ14,"")
... A202: =IF(بيانات!B202<>"",بيانات!A202,"") | B202: =IF(بيانات!B202<>"",بيانات!B202,"") | C202: =IF(بيانات!B202<>"",بيانات!C202,"") | D202: =IF(بيانات!B202<>"",بيانات!Z202,"") | F202: =IF(E202="","",E202+30) | H202: =IF(بيانات!B202<>"",بيانات!AE202,"") | I202: =IF(بيانات!B202<>"",بيانات!AJ202,"")

Sheet فئات_الأعمار
A1: 🏷️ تصنيف المنخرطين حسب الفئة العمرية والجنس — نادي RCS
S2: ذكر<13 | T2: أنثى<13 | U2: ذكر≥13 | V2: أنثى≥13
A3: فئة الذكور أقل من 13 سنة | E3: فئة الإناث أقل من 13 سنة | I3: فئة الذكور 13 سنة فما فوق | M3: فئة الإناث 13 سنة فما فوق | S3: =IF(AND(بيانات!$B3<>"",بيانات!$G3="ذكر",بيانات!$H3<13),COUNTA($S$3:S3),"") | T3: =IF(AND(بيانات!$B3<>"",بيانات!$G3="أنثى",بيانات!$H3<13),COUNTA($T$3:T3),"") | U3: =IF(AND(بيانات!$B3<>"",بيانات!$G3="ذكر",بيانات!$H3>=13),COUNTA($U$3:U3),"") | V3: =IF(AND(بيانات!$B3<>"",بيانات!$G3="أنثى",بيانات!$H3>=13),COUNTA($V$3:V3),"")
A4: ="العدد: " & COUNTIFS(بيانات!$G$3:$G$200,"ذكر",بيانات!$H$3:$H$200,"<13") | E4: ="العدد: " & COUNTIFS(بيانات!$G$3:$G$200,"أنثى",بيانات!$H$3:$H$200,"<13") | I4: ="العدد: " & COUNTIFS(بيانات!$G$3:$G$200,"ذكر",بيانات!$H$3:$H$200,">=13") | M4: ="العدد: " & COUNTIFS(بيانات!$G$3:$G$200,"أنثى",بيانات!$H$3:$H$200,">=13") | S4: =IF(AND(بيانات!$B4<>"",بيانات!$G4="ذكر",بيانات!$H4<13),COUNTA($S$3:S4),"") | T4: =IF(AND(بيانات!$B4<>"",بيانات!$G4="أنثى",بيانات!$H4<13),COUNTA($T$3:T4),"") | U4: =IF(AND(بيانات!$B4<>"",بيانات!$G4="ذكر",بيانات!$H4>=13),COUNTA($U$3:U4),"") | V4: =IF(AND(بيانات!$B4<>"",بيانات!$G4="أنثى",بيانات!$H4>=13),COUNTA($V$3:V4),"")
A5: رقم الملف | B5: اللقب والاسم | C5: العمر | E5: رقم الملف | F5: اللقب والاسم | G5: العمر | I5: رقم الملف | J5: اللقب والاسم | K5: العمر | M5: رقم الملف | N5: اللقب والاسم | O5: العمر | S5: =IF(AND(بيانات!$B5<>"",بيانات!$G5="ذكر",بيانات!$H5<13),COUNTA($S$3:S5),"") | T5: =IF(AND(بيانات!$B5<>"",بيانات!$G5="أنثى",بيانات!$H5<13),COUNTA($T$3:T5),"") | U5: =IF(AND(بيانات!$B5<>"",بيانات!$G5="ذكر",بيانات!$H5>=13),COUNTA($U$3:U5),"") | V5: =IF(AND(بيانات!$B5<>"",بيانات!$G5="أنثى",بيانات!$H5>=13),COUNTA($V$3:V5),"")
A6: =IFERROR(INDEX(بيانات!$A$3:$A$202,MATCH(1,$S$3:$S$202,0)),"") | B6: =IFERROR(INDEX(بيانات!$B$3:$B$202,MATCH(1,$S$3:$S$202,0))&" "&INDEX(بيانات!$C$3:$C$202,MATCH(1,$S$3:$S$202,0)),"") | C6: =IFERROR(INDEX(بيانات!$H$3:$H$202,MATCH(1,$S$3:$S$202,0)),"") | E6: =IFERROR(INDEX(بيانات!$A$3:$A$202,MATCH(1,$T$3:$T$202,0)),"") | F6: =IFERROR(INDEX(بيانات!$B$3:$B$202,MATCH(1,$T$3:$T$202,0))&" "&INDEX(بيانات!$C$3:$C$202,MATCH(1,$T$3:$T$202,0)),"") | G6: =IFERROR(INDEX(بيانات!$H$3:$H$202,MATCH(1,$T$3:$T$202,0)),"") | I6: =IFERROR(INDEX(بيانات!$A$3:$A$202,MATCH(1,$U$3:$U$202,0)),"") | J6: =IFERROR(INDEX(بيانات!$B$3:$B$202,MATCH(1,$U$3:$U$202,0))&" "&INDEX(بيانات!$C$3:$C$202,MATCH(1,$U$3:$U$202,0)),"") | K6: =IFERROR(INDEX(بيانات!$H$3:$H$202,MATCH(1,$U$3:$U$202,0)),"") | M6: =IFERROR(INDEX(بيانات!$A$3:$A$202,MATCH(1,$V$3:$V$202,0)),"") | N6: =IFERROR(INDEX(بيانات!$B$3:$B$202,MATCH(1,$V$3:$V$202,0))&" "&INDEX(بيانات!$C$3:$C$202,MATCH(1,$V$3:$V$202,0)),"") | O6: =IFERROR(INDEX(بيانات!$H$3:$H$202,MATCH(1,$V$3:$V$202,0)),"") | S6: =IF(AND(بيانات!$B6<>"",بيانات!$G6="ذكر",بيانات!$H6<13),COUNTA($S$3:S6),"") | T6: =IF(AND(بيانات!$B6<>"",بيانات!$G6="أنثى",بيانات!$H6<13),COUNTA($T$3:T6),"") | U6: =IF(AND(بيانات!$B6<>"",بيانات!$G6="ذكر",بيانات!$H6>=13),COUNTA($U$3:U6),"") | V6: =IF(AND(بيانات!$B6<>"",بيانات!$G6="أنثى",بيانات!$H6>=13),COUNTA($V$3:V6),"")
A7: =IFERROR(INDEX(بيانات!$A$3:$A$202,MATCH(2,$S$3:$S$202,0)),"") | B7: =IFERROR(INDEX(بيانات!$B$3:$B$202,MATCH(2,$S$3:$S$202,0))&" "&INDEX(بيانات!$C$3:$C$202,MATCH(2,$S$3:$S$202,0)),"") | C7: =IFERROR(INDEX(بيانات!$H$3:$H$202,MATCH(2,$S$3:$S$202,0)),"") | E7: =IFERROR(INDEX(بيانات!$A$3:$A$202,MATCH(2,$T$3:$T$202,0)),"") | F7: =IFERROR(INDEX(بيانات!$B$3:$B$202,MATCH(2,$T$3:$T$202,0))&" "&INDEX(بيانات!$C$3:$C$202,MATCH(2,$T$3:$T$202,0)),"") | G7: =IFERROR(INDEX(بيانات!$H$3:$H$202,MATCH(2,$T$3:$T$202,0)),"") | I7: =IFERROR(INDEX(بيانات!$A$3:$A$202,MATCH(2,$U$3:$U$202,0)),"") | J7: =IFERROR(INDEX(بيانات!$B$3:$B$202,MATCH(2,$U$3:$U$202,0))&" "&INDEX(بيانات!$C$3:$C$202,MATCH(2,$U$3:$U$202,0)),"") | K7: =IFERROR(INDEX(بيانات!$H$3:$H$202,MATCH(2,$U$3:$U$202,0)),"") | M7: =IFERROR(INDEX(بيانات!$A$3:$A$202,MATCH(2,$V$3:$V$202,0)),"") | N7: =IFERROR(INDEX(بيانات!$B$3:$B$202,MATCH(2,$V$3:$V$202,0))&" "&INDEX(بيانات!$C$3:$C$202,MATCH(2,$V$3:$V$202,0)),"") | O7: =IFERROR(INDEX(بيانات!$H$3:$H$202,MATCH(2,$V$3:$V$202,0)),"") | S7: =IF(AND(بيانات!$B7<>"",بيانات!$G7="ذكر",بيانات!$H7<13),COUNTA($S$3:S7),"") | T7: =IF(AND(بيانات!$B7<>"",بيانات!$G7="أنثى",بيانات!$H7<13),COUNTA($T$3:T7),"") | U7: =IF(AND(بيانات!$B7<>"",بيانات!$G7="ذكر",بيانات!$H7>=13),COUNTA($U$3:U7),"") | V7: =IF(AND(بيانات!$B7<>"",بيانات!$G7="أنثى",بيانات!$H7>=13),COUNTA($V$3:V7),"")
A8: =IFERROR(INDEX(بيانات!$A$3:$A$202,MATCH(3,$S$3:$S$202,0)),"") | B8: =IFERROR(INDEX(بيانات!$B$3:$B$202,MATCH(3,$S$3:$S$202,0))&" "&INDEX(بيانات!$C$3:$C$202,MATCH(3,$S$3:$S$202,0)),"") | C8: =IFERROR(INDEX(بيانات!$H$3:$H$202,MATCH(3,$S$3:$S$202,0)),"") | E8: =IFERROR(INDEX(بيانات!$A$3:$A$202,MATCH(3,$T$3:$T$202,0)),"") | F8: =IFERROR(INDEX(بيانات!$B$3:$B$202,MATCH(3,$T$3:$T$202,0))&" "&INDEX(بيانات!$C$3:$C$202,MATCH(3,$T$3:$T$202,0)),"") | G8: =IFERROR(INDEX(بيانات!$H$3:$H$202,MATCH(3,$T$3:$T$202,0)),"") | I8: =IFERROR(INDEX(بيانات!$A$3:$A$202,MATCH(3,$U$3:$U$202,0)),"") | J8: =IFERROR(INDEX(بيانات!$B$3:$B$202,MATCH(3,$U$3:$U$202,0))&" "&INDEX(بيانات!$C$3:$C$202,MATCH(3,$U$3:$U$202,0)),"") | K8: =IFERROR(INDEX(بيانات!$H$3:$H$202,MATCH(3,$U$3:$U$202,0)),"") | M8: =IFERROR(INDEX(بيانات!$A$3:$A$202,MATCH(3,$V$3:$V$202,0)),"") | N8: =IFERROR(INDEX(بيانات!$B$3:$B$202,MATCH(3,$V$3:$V$202,0))&" "&INDEX(بيانات!$C$3:$C$202,MATCH(3,$V$3:$V$202,0)),"") | O8: =IFERROR(INDEX(بيانات!$H$3:$H$202,MATCH(3,$V$3:$V$202,0)),"") | S8: =IF(AND(بيانات!$B8<>"",بيانات!$G8="ذكر",بيانات!$H8<13),COUNTA($S$3:S8),"") | T8: =IF(AND(بيانات!$B8<>"",بيانات!$G8="أنثى",بيانات!$H8<13),COUNTA($T$3:T8),"") | U8: =IF(AND(بيانات!$B8<>"",بيانات!$G8="ذكر",بيانات!$H8>=13),COUNTA($U$3:U8),"") | V8: =IF(AND(بيانات!$B8<>"",بيانات!$G8="أنثى",بيانات!$H8>=13),COUNTA($V$3:V8),"")
A9: =IFERROR(INDEX(بيانات!$A$3:$A$202,MATCH(4,$S$3:$S$202,0)),"") | B9: =IFERROR(INDEX(بيانات!$B$3:$B$202,MATCH(4,$S$3:$S$202,0))&" "&INDEX(بيانات!$C$3:$C$202,MATCH(4,$S$3:$S$202,0)),"") | C9: =IFERROR(INDEX(بيانات!$H$3:$H$202,MATCH(4,$S$3:$S$202,0)),"") | E9: =IFERROR(INDEX(بيانات!$A$3:$A$202,MATCH(4,$T$3:$T$202,0)),"") | F9: =IFERROR(INDEX(بيانات!$B$3:$B$202,MATCH(4,$T$3:$T$202,0))&" "&INDEX(بيانات!$C$3:$C$202,MATCH(4,$T$3:$T$202,0)),"") | G9: =IFERROR(INDEX(بيانات!$H$3:$H$202,MATCH(4,$T$3:$T$202,0)),"") | I9: =IFERROR(INDEX(بيانات!$A$3:$A$202,MATCH(4,$U$3:$U$202,0)),"") | J9: =IFERROR(INDEX(بيانات!$B$3:$B$202,MATCH(4,$U$3:$U$202,0))&" "&INDEX(بيانات!$C$3:$C$202,MATCH(4,$U$3:$U$202,0)),"") | K9: =IFERROR(INDEX(بيانات!$H$3:$H$202,MATCH(4,$U$3:$U$202,0)),"") | M9: =IFERROR(INDEX(بيانات!$A$3:$A$202,MATCH(4,$V$3:$V$202,0)),"") | N9: =IFERROR(INDEX(بيانات!$B$3:$B$202,MATCH(4,$V$3:$V$202,0))&" "&INDEX(بيانات!$C$3:$C$202,MATCH(4,$V$3:$V$202,0)),"") | O9: =IFERROR(INDEX(بيانات!$H$3:$H$202,MATCH(4,$V$3:$V$202,0)),"") | S9: =IF(AND(بيانات!$B9<>"",بيانات!$G9="ذكر",بيانات!$H9<13),COUNTA($S$3:S9),"") | T9: =IF(AND(بيانات!$B9<>"",بيانات!$G9="أنثى",بيانات!$H9<13),COUNTA($T$3:T9),"") | U9: =IF(AND(بيانات!$B9<>"",بيانات!$G9="ذكر",بيانات!$H9>=13),COUNTA($U$3:U9),"") | V9: =IF(AND(بيانات!$B9<>"",بيانات!$G9="أنثى",بيانات!$H9>=13),COUNTA($V$3:V9),"")
A10: =IFERROR(INDEX(بيانات!$A$3:$A$202,MATCH(5,$S$3:$S$202,0)),"") | B10: =IFERROR(INDEX(بيانات!$B$3:$B$202,MATCH(5,$S$3:$S$202,0))&" "&INDEX(بيانات!$C$3:$C$202,MATCH(5,$S$3:$S$202,0)),"") | C10: =IFERROR(INDEX(بيانات!$H$3:$H$202,MATCH(5,$S$3:$S$202,0)),"") | E10: =IFERROR(INDEX(بيانات!$A$3:$A$202,MATCH(5,$T$3:$T$202,0)),"") | F10: =IFERROR(INDEX(بيانات!$B$3:$B$202,MATCH(5,$T$3:$T$202,0))&" "&INDEX(بيانات!$C$3:$C$202,MATCH(5,$T$3:$T$202,0)),"") | G10: =IFERROR(INDEX(بيانات!$H$3:$H$202,MATCH(5,$T$3:$T$202,0)),"") | I10: =IFERROR(INDEX(بيانات!$A$3:$A$202,MATCH(5,$U$3:$U$202,0)),"") | J10: =IFERROR(INDEX(بيانات!$B$3:$B$202,MATCH(5,$U$3:$U$202,0))&" "&INDEX(بيانات!$C$3:$C$202,MATCH(5,$U$3:$U$202,0)),"") | K10: =IFERROR(INDEX(بيانات!$H$3:$H$202,MATCH(5,$U$3:$U$202,0)),"") | M10: =IFERROR(INDEX(بيانات!$A$3:$A$202,MATCH(5,$V$3:$V$202,0)),"") | N10: =IFERROR(INDEX(بيانات!$B$3:$B$202,MATCH(5,$V$3:$V$202,0))&" "&INDEX(بيانات!$C$3:$C$202,MATCH(5,$V$3:$V$202,0)),"") | O10: =IFERROR(INDEX(بيانات!$H$3:$H$202,MATCH(5,$V$3:$V$202,0)),"") | S10: =IF(AND(بيانات!$B10<>"",بيانات!$G10="ذكر",بيانات!$H10<13),COUNTA($S$3:S10),"") | T10: =IF(AND(بيانات!$B10<>"",بيانات!$G10="أنثى",بيانات!$H10<13),COUNTA($T$3:T10),"") | U10: =IF(AND(بيانات!$B10<>"",بيانات!$G10="ذكر",بيانات!$H10>=13),COUNTA($U$3:U10),"") | V10: =IF(AND(بيانات!$B10<>"",بيانات!$G10="أنثى",بيانات!$H10>=13),COUNTA($V$3:V10),"")
A11: =IFERROR(INDEX(بيانات!$A$3:$A$202,MATCH(6,$S$3:$S$202,0)),"") | B11: =IFERROR(INDEX(بيانات!$B$3:$B$202,MATCH(6,$S$3:$S$202,0))&" "&INDEX(بيانات!$C$3:$C$202,MATCH(6,$S$3:$S$202,0)),"") | C11: =IFERROR(INDEX(بيانات!$H$3:$H$202,MATCH(6,$S$3:$S$202,0)),"") | E11: =IFERROR(INDEX(بيانات!$A$3:$A$202,MATCH(6,$T$3:$T$202,0)),"") | F11: =IFERROR(INDEX(بيانات!$B$3:$B$202,MATCH(6,$T$3:$T$202,0))&" "&INDEX(بيانات!$C$3:$C$202,MATCH(6,$T$3:$T$202,0)),"") | G11: =IFERROR(INDEX(بيانات!$H$3:$H$202,MATCH(6,$T$3:$T$202,0)),"") | I11: =IFERROR(INDEX(بيانات!$A$3:$A$202,MATCH(6,$U$3:$U$202,0)),"") | J11: =IFERROR(INDEX(بيانات!$B$3:$B$202,MATCH(6,$U$3:$U$202,0))&" "&INDEX(بيانات!$C$3:$C$202,MATCH(6,$U$3:$U$202,0)),"") | K11: =IFERROR(INDEX(بيانات!$H$3:$H$202,MATCH(6,$U$3:$U$202,0)),"") | M11: =IFERROR(INDEX(بيانات!$A$3:$A$202,MATCH(6,$V$3:$V$202,0)),"") | N11: =IFERROR(INDEX(بيانات!$B$3:$B$202,MATCH(6,$V$3:$V$202,0))&" "&INDEX(بيانات!$C$3:$C$202,MATCH(6,$V$3:$V$202,0)),"") | O11: =IFERROR(INDEX(بيانات!$H$3:$H$202,MATCH(6,$V$3:$V$202,0)),"") | S11: =IF(AND(بيانات!$B11<>"",بيانات!$G11="ذكر",بيانات!$H11<13),COUNTA($S$3:S11),"") | T11: =IF(AND(بيانات!$B11<>"",بيانات!$G11="أنثى",بيانات!$H11<13),COUNTA($T$3:T11),"") | U11: =IF(AND(بيانات!$B11<>"",بيانات!$G11="ذكر",بيانات!$H11>=13),COUNTA($U$3:U11),"") | V11: =IF(AND(بيانات!$B11<>"",بيانات!$G11="أنثى",بيانات!$H11>=13),COUNTA($V$3:V11),"")
A12: =IFERROR(INDEX(بيانات!$A$3:$A$202,MATCH(7,$S$3:$S$202,0)),"") | B12: =IFERROR(INDEX(بيانات!$B$3:$B$202,MATCH(7,$S$3:$S$202,0))&" "&INDEX(بيانات!$C$3:$C$202,MATCH(7,$S$3:$S$202,0)),"") | C12: =IFERROR(INDEX(بيانات!$H$3:$H$202,MATCH(7,$S$3:$S$202,0)),"") | E12: =IFERROR(INDEX(بيانات!$A$3:$A$202,MATCH(7,$T$3:$T$202,0)),"") | F12: =IFERROR(INDEX(بيانات!$B$3:$B$202,MATCH(7,$T$3:$T$202,0))&" "&INDEX(بيانات!$C$3:$C$202,MATCH(7,$T$3:$T$202,0)),"") | G12: =IFERROR(INDEX(بيانات!$H$3:$H$202,MATCH(7,$T$3:$T$202,0)),"") | I12: =IFERROR(INDEX(بيانات!$A$3:$A$202,MATCH(7,$U$3:$U$202,0)),"") | J12: =IFERROR(INDEX(بيانات!$B$3:$B$202,MATCH(7,$U$3:$U$202,0))&" "&INDEX(بيانات!$C$3:$C$202,MATCH(7,$U$3:$U$202,0)),"") | K12: =IFERROR(INDEX(بيانات!$H$3:$H$202,MATCH(7,$U$3:$U$202,0)),"") | M12: =IFERROR(INDEX(بيانات!$A$3:$A$202,MATCH(7,$V$3:$V$202,0)),"") | N12: =IFERROR(INDEX(بيانات!$B$3:$B$202,MATCH(7,$V$3:$V$202,0))&" "&INDEX(بيانات!$C$3:$C$202,MATCH(7,$V$3:$V$202,0)),"") | O12: =IFERROR(INDEX(بيانات!$H$3:$H$202,MATCH(7,$V$3:$V$202,0)),"") | S12: =IF(AND(بيانات!$B12<>"",بيانات!$G12="ذكر",بيانات!$H12<13),COUNTA($S$3:S12),"") | T12: =IF(AND(بيانات!$B12<>"",بيانات!$G12="أنثى",بيانات!$H12<13),COUNTA($T$3:T12),"") | U12: =IF(AND(بيانات!$B12<>"",بيانات!$G12="ذكر",بيانات!$H12>=13),COUNTA($U$3:U12),"") | V12: =IF(AND(بيانات!$B12<>"",بيانات!$G12="أنثى",بيانات!$H12>=13),COUNTA($V$3:V12),"")
A13: =IFERROR(INDEX(بيانات!$A$3:$A$202,MATCH(8,$S$3:$S$202,0)),"") | B13: =IFERROR(INDEX(بيانات!$B$3:$B$202,MATCH(8,$S$3:$S$202,0))&" "&INDEX(بيانات!$C$3:$C$202,MATCH(8,$S$3:$S$202,0)),"") | C13: =IFERROR(INDEX(بيانات!$H$3:$H$202,MATCH(8,$S$3:$S$202,0)),"") | E13: =IFERROR(INDEX(بيانات!$A$3:$A$202,MATCH(8,$T$3:$T$202,0)),"") | F13: =IFERROR(INDEX(بيانات!$B$3:$B$202,MATCH(8,$T$3:$T$202,0))&" "&INDEX(بيانات!$C$3:$C$202,MATCH(8,$T$3:$T$202,0)),"") | G13: =IFERROR(INDEX(بيانات!$H$3:$H$202,MATCH(8,$T$3:$T$202,0)),"") | I13: =IFERROR(INDEX(بيانات!$A$3:$A$202,MATCH(8,$U$3:$U$202,0)),"") | J13: =IFERROR(INDEX(بيانات!$B$3:$B$202,MATCH(8,$U$3:$U$202,0))&" "&INDEX(بيانات!$C$3:$C$202,MATCH(8,$U$3:$U$202,0)),"") | K13: =IFERROR(INDEX(بيانات!$H$3:$H$202,MATCH(8,$U$3:$U$202,0)),"") | M13: =IFERROR(INDEX(بيانات!$A$3:$A$202,MATCH(8,$V$3:$V$202,0)),"") | N13: =IFERROR(INDEX(بيانات!$B$3:$B$202,MATCH(8,$V$3:$V$202,0))&" "&INDEX(بيانات!$C$3:$C$202,MATCH(8,$V$3:$V$202,0)),"") | O13: =IFERROR(INDEX(بيانات!$H$3:$H$202,MATCH(8,$V$3:$V$202,0)),"") | S13: =IF(AND(بيانات!$B13<>"",بيانات!$G13="ذكر",بيانات!$H13<13),COUNTA($S$3:S13),"") | T13: =IF(AND(بيانات!$B13<>"",بيانات!$G13="أنثى",بيانات!$H13<13),COUNTA($T$3:T13),"") | U13: =IF(AND(بيانات!$B13<>"",بيانات!$G13="ذكر",بيانات!$H13>=13),COUNTA($U$3:U13),"") | V13: =IF(AND(بيانات!$B13<>"",بيانات!$G13="أنثى",بيانات!$H13>=13),COUNTA($V$3:V13),"")
A14: =IFERROR(INDEX(بيانات!$A$3:$A$202,MATCH(9,$S$3:$S$202,0)),"") | B14: =IFERROR(INDEX(بيانات!$B$3:$B$202,MATCH(9,$S$3:$S$202,0))&" "&INDEX(بيانات!$C$3:$C$202,MATCH(9,$S$3:$S$202,0)),"") | C14: =IFERROR(INDEX(بيانات!$H$3:$H$202,MATCH(9,$S$3:$S$202,0)),"") | E14: =IFERROR(INDEX(بيانات!$A$3:$A$202,MATCH(9,$T$3:$T$202,0)),"") | F14: =IFERROR(INDEX(بيانات!$B$3:$B$202,MATCH(9,$T$3:$T$202,0))&" "&INDEX(بيانات!$C$3:$C$202,MATCH(9,$T$3:$T$202,0)),"") | G14: =IFERROR(INDEX(بيانات!$H$3:$H$202,MATCH(9,$T$3:$T$202,0)),"") | I14: =IFERROR(INDEX(بيانات!$A$3:$A$202,MATCH(9,$U$3:$U$202,0)),"") | J14: =IFERROR(INDEX(بيانات!$B$3:$B$202,MATCH(9,$U$3:$U$202,0))&" "&INDEX(بيانات!$C$3:$C$202,MATCH(9,$U$3:$U$202,0)),"") | K14: =IFERROR(INDEX(بيانات!$H$3:$H$202,MATCH(9,$U$3:$U$202,0)),"") | M14: =IFERROR(INDEX(بيانات!$A$3:$A$202,MATCH(9,$V$3:$V$202,0)),"") | N14: =IFERROR(INDEX(بيانات!$B$3:$B$202,MATCH(9,$V$3:$V$202,0))&" "&INDEX(بيانات!$C$3:$C$202,MATCH(9,$V$3:$V$202,0)),"") | O14: =IFERROR(INDEX(بيانات!$H$3:$H$202,MATCH(9,$V$3:$V$202,0)),"") | S14: =IF(AND(بيانات!$B14<>"",بيانات!$G14="ذكر",بيانات!$H14<13),COUNTA($S$3:S14),"") | T14: =IF(AND(بيانات!$B14<>"",بيانات!$G14="أنثى",بيانات!$H14<13),COUNTA($T$3:T14),"") | U14: =IF(AND(بيانات!$B14<>"",بيانات!$G14="ذكر",بيانات!$H14>=13),COUNTA($U$3:U14),"") | V14: =IF(AND(بيانات!$B14<>"",بيانات!$G14="أنثى",بيانات!$H14>=13),COUNTA($V$3:V14),"")
A15: =IFERROR(INDEX(بيانات!$A$3:$A$202,MATCH(10,$S$3:$S$202,0)),"") | B15: =IFERROR(INDEX(بيانات!$B$3:$B$202,MATCH(10,$S$3:$S$202,0))&" "&INDEX(بيانات!$C$3:$C$202,MATCH(10,$S$3:$S$202,0)),"") | C15: =IFERROR(INDEX(بيانات!$H$3:$H$202,MATCH(10,$S$3:$S$202,0)),"") | E15: =IFERROR(INDEX(بيانات!$A$3:$A$202,MATCH(10,$T$3:$T$202,0)),"") | F15: =IFERROR(INDEX(بيانات!$B$3:$B$202,MATCH(10,$T$3:$T$202,0))&" "&INDEX(بيانات!$C$3:$C$202,MATCH(10,$T$3:$T$202,0)),"") | G15: =IFERROR(INDEX(بيانات!$H$3:$H$202,MATCH(10,$T$3:$T$202,0)),"") | I15: =IFERROR(INDEX(بيانات!$A$3:$A$202,MATCH(10,$U$3:$U$202,0)),"") | J15: =IFERROR(INDEX(بيانات!$B$3:$B$202,MATCH(10,$U$3:$U$202,0))&" "&INDEX(بيانات!$C$3:$C$202,MATCH(10,$U$3:$U$202,0)),"") | K15: =IFERROR(INDEX(بيانات!$H$3:$H$202,MATCH(10,$U$3:$U$202,0)),"") | M15: =IFERROR(INDEX(بيانات!$A$3:$A$202,MATCH(10,$V$3:$V$202,0)),"") | N15: =IFERROR(INDEX(بيانات!$B$3:$B$202,MATCH(10,$V$3:$V$202,0))&" "&INDEX(بيانات!$C$3:$C$202,MATCH(10,$V$3:$V$202,0)),"") | O15: =IFERROR(INDEX(بيانات!$H$3:$H$202,MATCH(10,$V$3:$V$202,0)),"") | S15: =IF(AND(بيانات!$B15<>"",بيانات!$G15="ذكر",بيانات!$H15<13),COUNTA($S$3:S15),"") | T15: =IF(AND(بيانات!$B15<>"",بيانات!$G15="أنثى",بيانات!$H15<13),COUNTA($T$3:T15),"") | U15: =IF(AND(بيانات!$B15<>"",بيانات!$G15="ذكر",بيانات!$H15>=13),COUNTA($U$3:U15),"") | V15: =IF(AND(بيانات!$B15<>"",بيانات!$G15="أنثى",بيانات!$H15>=13),COUNTA($V$3:V15),"")
A16: =IFERROR(INDEX(بيانات!$A$3:$A$202,MATCH(11,$S$3:$S$202,0)),"") | B16: =IFERROR(INDEX(بيانات!$B$3:$B$202,MATCH(11,$S$3:$S$202,0))&" "&INDEX(بيانات!$C$3:$C$202,MATCH(11,$S$3:$S$202,0)),"") | C16: =IFERROR(INDEX(بيانات!$H$3:$H$202,MATCH(11,$S$3:$S$202,0)),"") | E16: =IFERROR(INDEX(بيانات!$A$3:$A$202,MATCH(11,$T$3:$T$202,0)),"") | F16: =IFERROR(INDEX(بيانات!$B$3:$B$202,MATCH(11,$T$3:$T$202,0))&" "&INDEX(بيانات!$C$3:$C$202,MATCH(11,$T$3:$T$202,0)),"") | G16: =IFERROR(INDEX(بيانات!$H$3:$H$202,MATCH(11,$T$3:$T$202,0)),"") | I16: =IFERROR(INDEX(بيانات!$A$3:$A$202,MATCH(11,$U$3:$U$202,0)),"") | J16: =IFERROR(INDEX(بيانات!$B$3:$B$202,MATCH(11,$U$3:$U$202,0))&" "&INDEX(بيانات!$C$3:$C$202,MATCH(11,$U$3:$U$202,0)),"") | K16: =IFERROR(INDEX(بيانات!$H$3:$H$202,MATCH(11,$U$3:$U$202,0)),"") | M16: =IFERROR(INDEX(بيانات!$A$3:$A$202,MATCH(11,$V$3:$V$202,0)),"") | N16: =IFERROR(INDEX(بيانات!$B$3:$B$202,MATCH(11,$V$3:$V$202,0))&" "&INDEX(بيانات!$C$3:$C$202,MATCH(11,$V$3:$V$202,0)),"") | O16: =IFERROR(INDEX(بيانات!$H$3:$H$202,MATCH(11,$V$3:$V$202,0)),"") | S16: =IF(AND(بيانات!$B16<>"",بيانات!$G16="ذكر",بيانات!$H16<13),COUNTA($S$3:S16),"") | T16: =IF(AND(بيانات!$B16<>"",بيانات!$G16="أنثى",بيانات!$H16<13),COUNTA($T$3:T16),"") | U16: =IF(AND(بيانات!$B16<>"",بيانات!$G16="ذكر",بيانات!$H16>=13),COUNTA($U$3:U16),"") | V16: =IF(AND(بيانات!$B16<>"",بيانات!$G16="أنثى",بيانات!$H16>=13),COUNTA($V$3:V16),"")
A17: =IFERROR(INDEX(بيانات!$A$3:$A$202,MATCH(12,$S$3:$S$202,0)),"") | B17: =IFERROR(INDEX(بيانات!$B$3:$B$202,MATCH(12,$S$3:$S$202,0))&" "&INDEX(بيانات!$C$3:$C$202,MATCH(12,$S$3:$S$202,0)),"") | C17: =IFERROR(INDEX(بيانات!$H$3:$H$202,MATCH(12,$S$3:$S$202,0)),"") | E17: =IFERROR(INDEX(بيانات!$A$3:$A$202,MATCH(12,$T$3:$T$202,0)),"") | F17: =IFERROR(INDEX(بيانات!$B$3:$B$202,MATCH(12,$T$3:$T$202,0))&" "&INDEX(بيانات!$C$3:$C$202,MATCH(12,$T$3:$T$202,0)),"") | G17: =IFERROR(INDEX(بيانات!$H$3:$H$202,MATCH(12,$T$3:$T$202,0)),"") | I17: =IFERROR(INDEX(بيانات!$A$3:$A$202,MATCH(12,$U$3:$U$202,0)),"") | J17: =IFERROR(INDEX(بيانات!$B$3:$B$202,MATCH(12,$U$3:$U$202,0))&" "&INDEX(بيانات!$C$3:$C$202,MATCH(12,$U$3:$U$202,0)),"") | K17: =IFERROR(INDEX(بيانات!$H$3:$H$202,MATCH(12,$U$3:$U$202,0)),"") | M17: =IFERROR(INDEX(بيانات!$A$3:$A$202,MATCH(12,$V$3:$V$202,0)),"") | N17: =IFERROR(INDEX(بيانات!$B$3:$B$202,MATCH(12,$V$3:$V$202,0))&" "&INDEX(بيانات!$C$3:$C$202,MATCH(12,$V$3:$V$202,0)),"") | O17: =IFERROR(INDEX(بيانات!$H$3:$H$202,MATCH(12,$V$3:$V$202,0)),"") | S17: =IF(AND(بيانات!$B17<>"",بيانات!$G17="ذكر",بيانات!$H17<13),COUNTA($S$3:S17),"") | T17: =IF(AND(بيانات!$B17<>"",بيانات!$G17="أنثى",بيانات!$H17<13),COUNTA($T$3:T17),"") | U17: =IF(AND(بيانات!$B17<>"",بيانات!$G17="ذكر",بيانات!$H17>=13),COUNTA($U$3:U17),"") | V17: =IF(AND(بيانات!$B17<>"",بيانات!$G17="أنثى",بيانات!$H17>=13),COUNTA($V$3:V17),"")
A18: =IFERROR(INDEX(بيانات!$A$3:$A$202,MATCH(13,$S$3:$S$202,0)),"") | B18: =IFERROR(INDEX(بيانات!$B$3:$B$202,MATCH(13,$S$3:$S$202,0))&" "&INDEX(بيانات!$C$3:$C$202,MATCH(13,$S$3:$S$202,0)),"") | C18: =IFERROR(INDEX(بيانات!$H$3:$H$202,MATCH(13,$S$3:$S$202,0)),"") | E18: =IFERROR(INDEX(بيانات!$A$3:$A$202,MATCH(13,$T$3:$T$202,0)),"") | F18: =IFERROR(INDEX(بيانات!$B$3:$B$202,MATCH(13,$T$3:$T$202,0))&" "&INDEX(بيانات!$C$3:$C$202,MATCH(13,$T$3:$T$202,0)),"") | G18: =IFERROR(INDEX(بيانات!$H$3:$H$202,MATCH(13,$T$3:$T$202,0)),"") | I18: =IFERROR(INDEX(بيانات!$A$3:$A$202,MATCH(13,$U$3:$U$202,0)),"") | J18: =IFERROR(INDEX(بيانات!$B$3:$B$202,MATCH(13,$U$3:$U$202,0))&" "&INDEX(بيانات!$C$3:$C$202,MATCH(13,$U$3:$U$202,0)),"") | K18: =IFERROR(INDEX(بيانات!$H$3:$H$202,MATCH(13,$U$3:$U$202,0)),"") | M18: =IFERROR(INDEX(بيانات!$A$3:$A$202,MATCH(13,$V$3:$V$202,0)),"") | N18: =IFERROR(INDEX(بيانات!$B$3:$B$202,MATCH(13,$V$3:$V$202,0))&" "&INDEX(بيانات!$C$3:$C$202,MATCH(13,$V$3:$V$202,0)),"") | O18: =IFERROR(INDEX(بيانات!$H$3:$H$202,MATCH(13,$V$3:$V$202,0)),"") | S18: =IF(AND(بيانات!$B18<>"",بيانات!$G18="ذكر",بيانات!$H18<13),COUNTA($S$3:S18),"") | T18: =IF(AND(بيانات!$B18<>"",بيانات!$G18="أنثى",بيانات!$H18<13),COUNTA($T$3:T18),"") | U18: =IF(AND(بيانات!$B18<>"",بيانات!$G18="ذكر",بيانات!$H18>=13),COUNTA($U$3:U18),"") | V18: =IF(AND(بيانات!$B18<>"",بيانات!$G18="أنثى",بيانات!$H18>=13),COUNTA($V$3:V18),"")
A19: =IFERROR(INDEX(بيانات!$A$3:$A$202,MATCH(14,$S$3:$S$202,0)),"") | B19: =IFERROR(INDEX(بيانات!$B$3:$B$202,MATCH(14,$S$3:$S$202,0))&" "&INDEX(بيانات!$C$3:$C$202,MATCH(14,$S$3:$S$202,0)),"") | C19: =IFERROR(INDEX(بيانات!$H$3:$H$202,MATCH(14,$S$3:$S$202,0)),"") | E19: =IFERROR(INDEX(بيانات!$A$3:$A$202,MATCH(14,$T$3:$T$202,0)),"") | F19: =IFERROR(INDEX(بيانات!$B$3:$B$202,MATCH(14,$T$3:$T$202,0))&" "&INDEX(بيانات!$C$3:$C$202,MATCH(14,$T$3:$T$202,0)),"") | G19: =IFERROR(INDEX(بيانات!$H$3:$H$202,MATCH(14,$T$3:$T$202,0)),"") | I19: =IFERROR(INDEX(بيانات!$A$3:$A$202,MATCH(14,$U$3:$U$202,0)),"") | J19: =IFERROR(INDEX(بيانات!$B$3:$B$202,MATCH(14,$U$3:$U$202,0))&" "&INDEX(بيانات!$C$3:$C$202,MATCH(14,$U$3:$U$202,0)),"") | K19: =IFERROR(INDEX(بيانات!$H$3:$H$202,MATCH(14,$U$3:$U$202,0)),"") | M19: =IFERROR(INDEX(بيانات!$A$3:$A$202,MATCH(14,$V$3:$V$202,0)),"") | N19: =IFERROR(INDEX(بيانات!$B$3:$B$202,MATCH(14,$V$3:$V$202,0))&" "&INDEX(بيانات!$C$3:$C$202,MATCH(14,$V$3:$V$202,0)),"") | O19: =IFERROR(INDEX(بيانات!$H$3:$H$202,MATCH(14,$V$3:$V$202,0)),"") | S19: =IF(AND(بيانات!$B19<>"",بيانات!$G19="ذكر",بيانات!$H19<13),COUNTA($S$3:S19),"") | T19: =IF(AND(بيانات!$B19<>"",بيانات!$G19="أنثى",بيانات!$H19<13),COUNTA($T$3:T19),"") | U19: =IF(AND(بيانات!$B19<>"",بيانات!$G19="ذكر",بيانات!$H19>=13),COUNTA($U$3:U19),"") | V19: =IF(AND(بيانات!$B19<>"",بيانات!$G19="أنثى",بيانات!$H19>=13),COUNTA($V$3:V19),"")
A20: =IFERROR(INDEX(بيانات!$A$3:$A$202,MATCH(15,$S$3:$S$202,0)),"") | B20: =IFERROR(INDEX(بيانات!$B$3:$B$202,MATCH(15,$S$3:$S$202,0))&" "&INDEX(بيانات!$C$3:$C$202,MATCH(15,$S$3:$S$202,0)),"") | C20: =IFERROR(INDEX(بيانات!$H$3:$H$202,MATCH(15,$S$3:$S$202,0)),"") | E20: =IFERROR(INDEX(بيانات!$A$3:$A$202,MATCH(15,$T$3:$T$202,0)),"") | F20: =IFERROR(INDEX(بيانات!$B$3:$B$202,MATCH(15,$T$3:$T$202,0))&" "&INDEX(بيانات!$C$3:$C$202,MATCH(15,$T$3:$T$202,0)),"") | G20: =IFERROR(INDEX(بيانات!$H$3:$H$202,MATCH(15,$T$3:$T$202,0)),"") | I20: =IFERROR(INDEX(بيانات!$A$3:$A$202,MATCH(15,$U$3:$U$202,0)),"") | J20: =IFERROR(INDEX(بيانات!$B$3:$B$202,MATCH(15,$U$3:$U$202,0))&" "&INDEX(بيانات!$C$3:$C$202,MATCH(15,$U$3:$U$202,0)),"") | K20: =IFERROR(INDEX(بيانات!$H$3:$H$202,MATCH(15,$U$3:$U$202,0)),"") | M20: =IFERROR(INDEX(بيانات!$A$3:$A$202,MATCH(15,$V$3:$V$202,0)),"") | N20: =IFERROR(INDEX(بيانات!$B$3:$B$202,MATCH(15,$V$3:$V$202,0))&" "&INDEX(بيانات!$C$3:$C$202,MATCH(15,$V$3:$V$202,0)),"") | O20: =IFERROR(INDEX(بيانات!$H$3:$H$202,MATCH(15,$V$3:$V$202,0)),"") | S20: =IF(AND(بيانات!$B20<>"",بيانات!$G20="ذكر",بيانات!$H20<13),COUNTA($S$3:S20),"") | T20: =IF(AND(بيانات!$B20<>"",بيانات!$G20="أنثى",بيانات!$H20<13),COUNTA($T$3:T20),"") | U20: =IF(AND(بيانات!$B20<>"",بيانات!$G20="ذكر",بيانات!$H20>=13),COUNTA($U$3:U20),"") | V20: =IF(AND(بيانات!$B20<>"",بيانات!$G20="أنثى",بيانات!$H20>=13),COUNTA($V$3:V20),"")
A21: =IFERROR(INDEX(بيانات!$A$3:$A$202,MATCH(16,$S$3:$S$202,0)),"") | B21: =IFERROR(INDEX(بيانات!$B$3:$B$202,MATCH(16,$S$3:$S$202,0))&" "&INDEX(بيانات!$C$3:$C$202,MATCH(16,$S$3:$S$202,0)),"") | C21: =IFERROR(INDEX(بيانات!$H$3:$H$202,MATCH(16,$S$3:$S$202,0)),"") | E21: =IFERROR(INDEX(بيانات!$A$3:$A$202,MATCH(16,$T$3:$T$202,0)),"") | F21: =IFERROR(INDEX(بيانات!$B$3:$B$202,MATCH(16,$T$3:$T$202,0))&" "&INDEX(بيانات!$C$3:$C$202,MATCH(16,$T$3:$T$202,0)),"") | G21: =IFERROR(INDEX(بيانات!$H$3:$H$202,MATCH(16,$T$3:$T$202,0)),"") | I21: =IFERROR(INDEX(بيانات!$A$3:$A$202,MATCH(16,$U$3:$U$202,0)),"") | J21: =IFERROR(INDEX(بيانات!$B$3:$B$202,MATCH(16,$U$3:$U$202,0))&" "&INDEX(بيانات!$C$3:$C$202,MATCH(16,$U$3:$U$202,0)),"") | K21: =IFERROR(INDEX(بيانات!$H$3:$H$202,MATCH(16,$U$3:$U$202,0)),"") | M21: =IFERROR(INDEX(بيانات!$A$3:$A$202,MATCH(16,$V$3:$V$202,0)),"") | N21: =IFERROR(INDEX(بيانات!$B$3:$B$202,MATCH(16,$V$3:$V$202,0))&" "&INDEX(بيانات!$C$3:$C$202,MATCH(16,$V$3:$V$202,0)),"") | O21: =IFERROR(INDEX(بيانات!$H$3:$H$202,MATCH(16,$V$3:$V$202,0)),"") | S21: =IF(AND(بيانات!$B21<>"",بيانات!$G21="ذكر",بيانات!$H21<13),COUNTA($S$3:S21),"") | T21: =IF(AND(بيانات!$B21<>"",بيانات!$G21="أنثى",بيانات!$H21<13),COUNTA($T$3:T21),"") | U21: =IF(AND(بيانات!$B21<>"",بيانات!$G21="ذكر",بيانات!$H21>=13),COUNTA($U$3:U21),"") | V21: =IF(AND(بيانات!$B21<>"",بيانات!$G21="أنثى",بيانات!$H21>=13),COUNTA($V$3:V21),"")
A22: =IFERROR(INDEX(بيانات!$A$3:$A$202,MATCH(17,$S$3:$S$202,0)),"") | B22: =IFERROR(INDEX(بيانات!$B$3:$B$202,MATCH(17,$S$3:$S$202,0))&" "&INDEX(بيانات!$C$3:$C$202,MATCH(17,$S$3:$S$202,0)),"") | C22: =IFERROR(INDEX(بيانات!$H$3:$H$202,MATCH(17,$S$3:$S$202,0)),"") | E22: =IFERROR(INDEX(بيانات!$A$3:$A$202,MATCH(17,$T$3:$T$202,0)),"") | F22: =IFERROR(INDEX(بيانات!$B$3:$B$202,MATCH(17,$T$3:$T$202,0))&" "&INDEX(بيانات!$C$3:$C$202,MATCH(17,$T$3:$T$202,0)),"") | G22: =IFERROR(INDEX(بيانات!$H$3:$H$202,MATCH(17,$T$3:$T$202,0)),"") | I22: =IFERROR(INDEX(بيانات!$A$3:$A$202,MATCH(17,$U$3:$U$202,0)),"") | J22: =IFERROR(INDEX(بيانات!$B$3:$B$202,MATCH(17,$U$3:$U$202,0))&" "&INDEX(بيانات!$C$3:$C$202,MATCH(17,$U$3:$U$202,0)),"") | K22: =IFERROR(INDEX(بيانات!$H$3:$H$202,MATCH(17,$U$3:$U$202,0)),"") | M22: =IFERROR(INDEX(بيانات!$A$3:$A$202,MATCH(17,$V$3:$V$202,0)),"") | N22: =IFERROR(INDEX(بيانات!$B$3:$B$202,MATCH(17,$V$3:$V$202,0))&" "&INDEX(بيانات!$C$3:$C$202,MATCH(17,$V$3:$V$202,0)),"") | O22: =IFERROR(INDEX(بيانات!$H$3:$H$202,MATCH(17,$V$3:$V$202,0)),"") | S22: =IF(AND(بيانات!$B22<>"",بيانات!$G22="ذكر",بيانات!$H22<13),COUNTA($S$3:S22),"") | T22: =IF(AND(بيانات!$B22<>"",بيانات!$G22="أنثى",بيانات!$H22<13),COUNTA($T$3:T22),"") | U22: =IF(AND(بيانات!$B22<>"",بيانات!$G22="ذكر",بيانات!$H22>=13),COUNTA($U$3:U22),"") | V22: =IF(AND(بيانات!$B22<>"",بيانات!$G22="أنثى",بيانات!$H22>=13),COUNTA($V$3:V22),"")
A23: =IFERROR(INDEX(بيانات!$A$3:$A$202,MATCH(18,$S$3:$S$202,0)),"") | B23: =IFERROR(INDEX(بيانات!$B$3:$B$202,MATCH(18,$S$3:$S$202,0))&" "&INDEX(بيانات!$C$3:$C$202,MATCH(18,$S$3:$S$202,0)),"") | C23: =IFERROR(INDEX(بيانات!$H$3:$H$202,MATCH(18,$S$3:$S$202,0)),"") | E23: =IFERROR(INDEX(بيانات!$A$3:$A$202,MATCH(18,$T$3:$T$202,0)),"") | F23: =IFERROR(INDEX(بيانات!$B$3:$B$202,MATCH(18,$T$3:$T$202,0))&" "&INDEX(بيانات!$C$3:$C$202,MATCH(18,$T$3:$T$202,0)),"") | G23: =IFERROR(INDEX(بيانات!$H$3:$H$202,MATCH(18,$T$3:$T$202,0)),"") | I23: =IFERROR(INDEX(بيانات!$A$3:$A$202,MATCH(18,$U$3:$U$202,0)),"") | J23: =IFERROR(INDEX(بيانات!$B$3:$B$202,MATCH(18,$U$3:$U$202,0))&" "&INDEX(بيانات!$C$3:$C$202,MATCH(18,$U$3:$U$202,0)),"") | K23: =IFERROR(INDEX(بيانات!$H$3:$H$202,MATCH(18,$U$3:$U$202,0)),"") | M23: =IFERROR(INDEX(بيانات!$A$3:$A$202,MATCH(18,$V$3:$V$202,0)),"") | N23: =IFERROR(INDEX(بيانات!$B$3:$B$202,MATCH(18,$V$3:$V$202,0))&" "&INDEX(بيانات!$C$3:$C$202,MATCH(18,$V$3:$V$202,0)),"") | O23: =IFERROR(INDEX(بيانات!$H$3:$H$202,MATCH(18,$V$3:$V$202,0)),"") | S23: =IF(AND(بيانات!$B23<>"",بيانات!$G23="ذكر",بيانات!$H23<13),COUNTA($S$3:S23),"") | T23: =IF(AND(بيانات!$B23<>"",بيانات!$G23="أنثى",بيانات!$H23<13),COUNTA($T$3:T23),"") | U23: =IF(AND(بيانات!$B23<>"",بيانات!$G23="ذكر",بيانات!$H23>=13),COUNTA($U$3:U23),"") | V23: =IF(AND(بيانات!$B23<>"",بيانات!$G23="أنثى",بيانات!$H23>=13),COUNTA($V$3:V23),"")
A24: =IFERROR(INDEX(بيانات!$A$3:$A$202,MATCH(19,$S$3:$S$202,0)),"") | B24: =IFERROR(INDEX(بيانات!$B$3:$B$202,MATCH(19,$S$3:$S$202,0))&" "&INDEX(بيانات!$C$3:$C$202,MATCH(19,$S$3:$S$202,0)),"") | C24: =IFERROR(INDEX(بيانات!$H$3:$H$202,MATCH(19,$S$3:$S$202,0)),"") | E24: =IFERROR(INDEX(بيانات!$A$3:$A$202,MATCH(19,$T$3:$T$202,0)),"") | F24: =IFERROR(INDEX(بيانات!$B$3:$B$202,MATCH(19,$T$3:$T$202,0))&" "&INDEX(بيانات!$C$3:$C$202,MATCH(19,$T$3:$T$202,0)),"") | G24: =IFERROR(INDEX(بيانات!$H$3:$H$202,MATCH(19,$T$3:$T$202,0)),"") | I24: =IFERROR(INDEX(بيانات!$A$3:$A$202,MATCH(19,$U$3:$U$202,0)),"") | J24: =IFERROR(INDEX(بيانات!$B$3:$B$202,MATCH(19,$U$3:$U$202,0))&" "&INDEX(بيانات!$C$3:$C$202,MATCH(19,$U$3:$U$202,0)),"") | K24: =IFERROR(INDEX(بيانات!$H$3:$H$202,MATCH(19,$U$3:$U$202,0)),"") | M24: =IFERROR(INDEX(بيانات!$A$3:$A$202,MATCH(19,$V$3:$V$202,0)),"") | N24: =IFERROR(INDEX(بيانات!$B$3:$B$202,MATCH(19,$V$3:$V$202,0))&" "&INDEX(بيانات!$C$3:$C$202,MATCH(19,$V$3:$V$202,0)),"") | O24: =IFERROR(INDEX(بيانات!$H$3:$H$202,MATCH(19,$V$3:$V$202,0)),"") | S24: =IF(AND(بيانات!$B24<>"",بيانات!$G24="ذكر",بيانات!$H24<13),COUNTA($S$3:S24),"") | T24: =IF(AND(بيانات!$B24<>"",بيانات!$G24="أنثى",بيانات!$H24<13),COUNTA($T$3:T24),"") | U24: =IF(AND(بيانات!$B24<>"",بيانات!$G24="ذكر",بيانات!$H24>=13),COUNTA($U$3:U24),"") | V24: =IF(AND(بيانات!$B24<>"",بيانات!$G24="أنثى",بيانات!$H24>=13),COUNTA($V$3:V24),"")
